Workbook

Sheet Final
A6: Month | B6: Hours | C6: Max_Capacity | D6: X_Stockpile_t | E6: X_Colombian_t | F6: X_Russian_t | G6: X_Scottish_t | H6: X_Wood_t | I6: Thermal_Input_GJ | J6: Total_MWh | K6: Wood_Chips_MWh | L6: Price_per MWh | M6: Revenue | N6: ROC_Revenue | O6: Grid_Charge | P6: Fuel_Cost | Q6: CO2_Cost | R6: Profit | S6: Wood_Thermal_GJ | T6: SO2_tonnes | U6: Biomass_share | V6: Thermal_Input_GJ*0.1 | W6: Coal fule | Y6: Wood_Chips_Constraint
A7: June - Weekday Peak | B7: 264 | C7: =B7*1000 -> 264000 | D7: 94687.552 | E7: 0 | F7: 0 | G7: 0 | H7: 15085.714 | I7: =SUMPRODUCT(D7:H7, N$31:R$31) -> 2715428.6 | J7: =(SUMPRODUCT(D7:H7, N$31:R$31)*0.35)/3.6 -> 264000 | K7: =($R$31*H7*0.35)/3.6 -> 26400 | L7: =VLOOKUP(A7,F29:G49,2,FALSE) -> 36 | M7: =L7*J7 -> 9504000 | N7: =45*($R$31*H7*0.35)/3.6 -> 1188000 | O7: =SUMPRODUCT(D7:H7, N$31:R$31)*0.35*0.65/3.6 -> 171600 | P7: =SUMPRODUCT(D7:H7, N$30:R$30) -> 5142775.4 | Q7: =J7*0.8*0.87*15 -> 2756160 | R7: =IFERROR(M7+N7-O7-P7-Q7,0) -> 2621464.6 | S7: =H7*$R$31 -> 271542.86 | T7: =SUMPRODUCT(D7:H7, N$32:R$32)*0.01 -> 1308.1968 | U7: =IFERROR(S7/I7,0) -> 0.1 | V7: =0.1*I7 -> 271542.86 | W7: =SUMPRODUCT($N$31:$Q$31,D7:G7) -> 2443885.7 | Y7: =K7-0.1*J7 -> 0
A8: June - Weekday Off-peak | B8: 264 | C8: =B8*1000 -> 264000 | D8: 0 | E8: 0 | F8: 0 | G8: 0 | H8: 0 | I8: =SUMPRODUCT(D8:H8, N$31:R$31) -> 0 | J8: =(SUMPRODUCT(D8:H8, N$31:R$31)*0.35)/3.6 -> 0 | K8: =($R$31*H8*0.35)/3.6 -> 0 | L8: =VLOOKUP(A8,F30:G51,2,FALSE) -> 27 | M8: =L8*J8 -> 0 | N8: =45*($R$31*H8*0.35)/3.6 -> 0 | O8: =SUMPRODUCT(D8:H8, N$31:R$31)*0.35*0.65/3.6 -> 0 | P8: =SUMPRODUCT(D8:H8, N$30:R$30) -> 0 | Q8: =J8*0.8*0.87*15 -> 0 | R8: =IFERROR(M8+N8-O8-P8-Q8,0) -> 0 | S8: =H8*$R$31 -> 0 | T8: =SUMPRODUCT(D8:H8, N$32:R$32)*0.01 -> 0 | U8: =IFERROR(S8/I8,0) -> 0 | V8: =0.1*I8 -> 0 | W8: =SUMPRODUCT($N$31:$Q$31,D8:G8) -> 0 | Y8: =K8-0.1*J8 -> 0
A9: June - Weekend Peak | B9: 96 | C9: =B9*1000 -> 96000 | D9: 34431.837 | E9: 0 | F9: 0 | G9: 0 | H9: 5485.7143 | I9: =SUMPRODUCT(D9:H9, N$31:R$31) -> 987428.57 | J9: =(SUMPRODUCT(D9:H9, N$31:R$31)*0.35)/3.6 -> 96000 | K9: =($R$31*H9*0.35)/3.6 -> 9600 | L9: =VLOOKUP(A9,F31:G52,2,FALSE) -> 33.5 | M9: =L9*J9 -> 3216000 | N9: =45*($R$31*H9*0.35)/3.6 -> 432000 | O9: =SUMPRODUCT(D9:H9, N$31:R$31)*0.35*0.65/3.6 -> 62400 | P9: =SUMPRODUCT(D9:H9, N$30:R$30) -> 1870100.1 | Q9: =J9*0.8*0.87*15 -> 1002240 | R9: =IFERROR(M9+N9-O9-P9-Q9,0) -> 713259.87 | S9: =H9*$R$31 -> 98742.857 | T9: =SUMPRODUCT(D9:H9, N$32:R$32)*0.01 -> 475.70792 | U9: =IFERROR(S9/I9,0) -> 0.1 | V9: =0.1*I9 -> 98742.857 | W9: =SUMPRODUCT($N$31:$Q$31,D9:G9) -> 888685.71 | Y9: =K9-0.1*J9 -> 0
A10: June - Weekend Off-peak | B10: 96 | C10: =B10*1000 -> 96000 | D10: 0 | E10: 0 | F10: 0 | G10: 0 | H10: 0 | I10: =SUMPRODUCT(D10:H10, N$31:R$31) -> 0 | J10: =(SUMPRODUCT(D10:H10, N$31:R$31)*0.35)/3.6 -> 0 | K10: =($R$31*H10*0.35)/3.6 -> 0 | L10: =VLOOKUP(A10,F32:G53,2,FALSE) -> 26.2 | M10: =L10*J10 -> 0 | N10: =45*($R$31*H10*0.35)/3.6 -> 0 | O10: =SUMPRODUCT(D10:H10, N$31:R$31)*0.35*0.65/3.6 -> 0 | P10: =SUMPRODUCT(D10:H10, N$30:R$30) -> 0 | Q10: =J10*0.8*0.87*15 -> 0 | R10: =IFERROR(M10+N10-O10-P10-Q10,0) -> 0 | S10: =H10*$R$31 -> 0 | T10: =SUMPRODUCT(D10:H10, N$32:R$32)*0.01 -> 0 | U10: =IFERROR(S10/I10,0) -> 0 | V10: =0.1*I10 -> 0 | W10: =SUMPRODUCT($N$31:$Q$31,D10:G10) -> 0 | Y10: =K10-0.1*J10 -> 0
A11: July - Weekday Peak | B11: 264 | C11: =B11*1000 -> 264000 | D11: 94687.552 | E11: 0 | F11: 0 | G11: 0 | H11: 15085.714 | I11: =SUMPRODUCT(D11:H11, N$31:R$31) -> 2715428.6 | J11: =(SUMPRODUCT(D11:H11, N$31:R$31)*0.35)/3.6 -> 264000 | K11: =($R$31*H11*0.35)/3.6 -> 26400 | L11: =VLOOKUP(A11,F33:G54,2,FALSE) -> 36.35 | M11: =L11*J11 -> 9596400 | N11: =45*($R$31*H11*0.35)/3.6 -> 1188000 | O11: =SUMPRODUCT(D11:H11, N$31:R$31)*0.35*0.65/3.6 -> 171600 | P11: =SUMPRODUCT(D11:H11, N$30:R$30) -> 5142775.4 | Q11: =J11*0.8*0.87*15 -> 2756160 | R11: =IFERROR(M11+N11-O11-P11-Q11,0) -> 2713864.6 | S11: =H11*$R$31 -> 271542.86 | T11: =SUMPRODUCT(D11:H11, N$32:R$32)*0.01 -> 1308.1968 | U11: =IFERROR(S11/I11,0) -> 0.1 | V11: =0.1*I11 -> 271542.86 | W11: =SUMPRODUCT($N$31:$Q$31,D11:G11) -> 2443885.7 | Y11: =K11-0.1*J11 -> 0
A12: July - Weekday Off-peak | B12: 264 | C12: =B12*1000 -> 264000 | D12: 0 | E12: 0 | F12: 0 | G12: 0 | H12: 0 | I12: =SUMPRODUCT(D12:H12, N$31:R$31) -> 0 | J12: =(SUMPRODUCT(D12:H12, N$31:R$31)*0.35)/3.6 -> 0 | K12: =($R$31*H12*0.35)/3.6 -> 0 | L12: =VLOOKUP(A12,F34:G55,2,FALSE) -> 27 | M12: =L12*J12 -> 0 | N12: =45*($R$31*H12*0.35)/3.6 -> 0 | O12: =SUMPRODUCT(D12:H12, N$31:R$31)*0.35*0.65/3.6 -> 0 | P12: =SUMPRODUCT(D12:H12, N$30:R$30) -> 0 | Q12: =J12*0.8*0.87*15 -> 0 | R12: =IFERROR(M12+N12-O12-P12-Q12,0) -> 0 | S12: =H12*$R$31 -> 0 | T12: =SUMPRODUCT(D12:H12, N$32:R$32)*0.01 -> 0 | U12: =IFERROR(S12/I12,0) -> 0 | V12: =0.1*I12 -> 0 | W12: =SUMPRODUCT($N$31:$Q$31,D12:G12) -> 0 | Y12: =K12-0.1*J12 -> 0
A13: July - Weekend Peak | B13: 108 | C13: =B13*1000 -> 108000 | D13: 38735.817 | E13: 0 | F13: 0 | G13: 0 | H13: 6171.4286 | I13: =SUMPRODUCT(D13:H13, N$31:R$31) -> 1110857.1 | J13: =(SUMPRODUCT(D13:H13, N$31:R$31)*0.35)/3.6 -> 108000 | K13: =($R$31*H13*0.35)/3.6 -> 10800 | L13: =VLOOKUP(A13,F35:G56,2,FALSE) -> 34.3 | M13: =L13*J13 -> 3704400 | N13: =45*($R$31*H13*0.35)/3.6 -> 486000 | O13: =SUMPRODUCT(D13:H13, N$31:R$31)*0.35*0.65/3.6 -> 70200 | P13: =SUMPRODUCT(D13:H13, N$30:R$30) -> 2103862.6 | Q13: =J13*0.8*0.87*15 -> 1127520 | R13: =IFERROR(M13+N13-O13-P13-Q13,0) -> 888817.36 | S13: =H13*$R$31 -> 111085.71 | T13: =SUMPRODUCT(D13:H13, N$32:R$32)*0.01 -> 535.17141 | U13: =IFERROR(S13/I13,0) -> 0.1 | V13: =0.1*I13 -> 111085.71 | W13: =SUMPRODUCT($N$31:$Q$31,D13:G13) -> 999771.43 | Y13: =K13-0.1*J13 -> 0
A14: July - Weekend Off-peak | B14: 108 | C14: =B14*1000 -> 108000 | D14: 0 | E14: 0 | F14: 0 | G14: 0 | H14: 0 | I14: =SUMPRODUCT(D14:H14, N$31:R$31) -> 0 | J14: =(SUMPRODUCT(D14:H14, N$31:R$31)*0.35)/3.6 -> 0 | K14: =($R$31*H14*0.35)/3.6 -> 0 | L14: =VLOOKUP(A14,F36:G57,2,FALSE) -> 26.3 | M14: =L14*J14 -> 0 | N14: =45*($R$31*H14*0.35)/3.6 -> 0 | O14: =SUMPRODUCT(D14:H14, N$31:R$31)*0.35*0.65/3.6 -> 0 | P14: =SUMPRODUCT(D14:H14, N$30:R$30) -> 0 | Q14: =J14*0.8*0.87*15 -> 0 | R14: =IFERROR(M14+N14-O14-P14-Q14,0) -> 0 | S14: =H14*$R$31 -> 0 | T14: =SUMPRODUCT(D14:H14, N$32:R$32)*0.01 -> 0 | U14: =IFERROR(S14/I14,0) -> 0 | V14: =0.1*I14 -> 0 | W14: =SUMPRODUCT($N$31:$Q$31,D14:G14) -> 0 | Y14: =K14-0.1*J14 -> 0
A15: August - Weekday Peak | B15: 264 | C15: =B15*1000 -> 264000 | D15: 94687.552 | E15: 0 | F15: 0 | G15: 0 | H15: 15085.714 | I15: =SUMPRODUCT(D15:H15, N$31:R$31) -> 2715428.6 | J15: =(SUMPRODUCT(D15:H15, N$31:R$31)*0.35)/3.6 -> 264000 | K15: =($R$31*H15*0.35)/3.6 -> 26400 | L15: =VLOOKUP(A15,F37:G58,2,FALSE) -> 37.65 | M15: =L15*J15 -> 9939600 | N15: =45*($R$31*H15*0.35)/3.6 -> 1188000 | O15: =SUMPRODUCT(D15:H15, N$31:R$31)*0.35*0.65/3.6 -> 171600 | P15: =SUMPRODUCT(D15:H15, N$30:R$30) -> 5142775.4 | Q15: =J15*0.8*0.87*15 -> 2756160 | R15: =IFERROR(M15+N15-O15-P15-Q15,0) -> 3057064.6 | S15: =H15*$R$31 -> 271542.86 | T15: =SUMPRODUCT(D15:H15, N$32:R$32)*0.01 -> 1308.1968 | U15: =IFERROR(S15/I15,0) -> 0.1 | V15: =0.1*I15 -> 271542.86 | W15: =SUMPRODUCT($N$31:$Q$31,D15:G15) -> 2443885.7 | Y15: =K15-0.1*J15 -> 0
A16: August - Weekday Off-peak | B16: 264 | C16: =B16*1000 -> 264000 | D16: 94687.552 | E16: 0 | F16: 0 | G16: 0 | H16: 15085.714 | I16: =SUMPRODUCT(D16:H16, N$31:R$31) -> 2715428.6 | J16: =(SUMPRODUCT(D16:H16, N$31:R$31)*0.35)/3.6 -> 264000 | K16: =($R$31*H16*0.35)/3.6 -> 26400 | L16: =VLOOKUP(A16,F38:G59,2,FALSE) -> 28.2 | M16: =L16*J16 -> 7444800 | N16: =45*($R$31*H16*0.35)/3.6 -> 1188000 | O16: =SUMPRODUCT(D16:H16, N$31:R$31)*0.35*0.65/3.6 -> 171600 | P16: =SUMPRODUCT(D16:H16, N$30:R$30) -> 5142775.4 | Q16: =J16*0.8*0.87*15 -> 2756160 | R16: =IFERROR(M16+N16-O16-P16-Q16,0) -> 562264.65 | S16: =H16*$R$31 -> 271542.86 | T16: =SUMPRODUCT(D16:H16, N$32:R$32)*0.01 -> 1308.1968 | U16: =IFERROR(S16/I16,0) -> 0.1 | V16: =0.1*I16 -> 271542.86 | W16: =SUMPRODUCT($N$31:$Q$31,D16:G16) -> 2443885.7 | Y16: =K16-0.1*J16 -> 0
A17: August - Weekend Peak | B17: 108 | C17: =B17*1000 -> 108000 | D17: 38735.817 | E17: 0 | F17: 0 | G17: 0 | H17: 6171.4286 | I17: =SUMPRODUCT(D17:H17, N$31:R$31) -> 1110857.1 | J17: =(SUMPRODUCT(D17:H17, N$31:R$31)*0.35)/3.6 -> 108000 | K17: =($R$31*H17*0.35)/3.6 -> 10800 | L17: =VLOOKUP(A17,F39:G60,2,FALSE) -> 35.65 | M17: =L17*J17 -> 3850200 | N17: =45*($R$31*H17*0.35)/3.6 -> 486000 | O17: =SUMPRODUCT(D17:H17, N$31:R$31)*0.35*0.65/3.6 -> 70200 | P17: =SUMPRODUCT(D17:H17, N$30:R$30) -> 2103862.6 | Q17: =J17*0.8*0.87*15 -> 1127520 | R17: =IFERROR(M17+N17-O17-P17-Q17,0) -> 1034617.4 | S17: =H17*$R$31 -> 111085.71 | T17: =SUMPRODUCT(D17:H17, N$32:R$32)*0.01 -> 535.17141 | U17: =IFERROR(S17/I17,0) -> 0.1 | V17: =0.1*I17 -> 111085.71 | W17: =SUMPRODUCT($N$31:$Q$31,D17:G17) -> 999771.43 | Y17: =K17-0.1*J17 -> 0
A18: August - Weekend Off-peak | B18: 108 | C18: =B18*1000 -> 108000 | D18: 0 | E18: 0 | F18: 0 | G18: 0 | H18: 0 | I18: =SUMPRODUCT(D18:H18, N$31:R$31) -> 0 | J18: =(SUMPRODUCT(D18:H18, N$31:R$31)*0.35)/3.6 -> 0 | K18: =($R$31*H18*0.35)/3.6 -> 0 | L18: =VLOOKUP(A18,F40:G61,2,FALSE) -> 27.5 | M18: =L18*J18 -> 0 | N18: =45*($R$31*H18*0.35)/3.6 -> 0 | O18: =SUMPRODUCT(D18:H18, N$31:R$31)*0.35*0.65/3.6 -> 0 | P18: =SUMPRODUCT(D18:H18, N$30:R$30) -> 0 | Q18: =J18*0.8*0.87*15 -> 0 | R18: =IFERROR(M18+N18-O18-P18-Q18,0) -> 0 | S18: =H18*$R$31 -> 0 | T18: =SUMPRODUCT(D18:H18, N$32:R$32)*0.01 -> 0 | U18: =IFERROR(S18/I18,0) -> 0 | V18: =0.1*I18 -> 0 | W18: =SUMPRODUCT($N$31:$Q$31,D18:G18) -> 0 | Y18: =K18-0.1*J18 -> 0
A19: September - Weekday Peak | B19: 264 | C19: =B19*1000 -> 264000 | D19: 0 | E19: 0 | F19: 67627.445 | G19: 30038.676 | H19: 15085.714 | I19: =SUMPRODUCT(D19:H19, N$31:R$31) -> 2715428.6 | J19: =(SUMPRODUCT(D19:H19, N$31:R$31)*0.35)/3.6 -> 264000 | K19: =($R$31*H19*0.35)/3.6 -> 26400 | L19: =VLOOKUP(A19,F41:G62,2,FALSE) -> 38.35 | M19: =L19*J19 -> 10124400 | N19: =45*($R$31*H19*0.35)/3.6 -> 1188000 | O19: =SUMPRODUCT(D19:H19, N$31:R$31)*0.35*0.65/3.6 -> 171600 | P19: =SUMPRODUCT(D19:H19, N$30:R$30) -> 5336579.6 | Q19: =J19*0.8*0.87*15 -> 2756160 | R19: =IFERROR(M19+N19-O19-P19-Q19,0) -> 3048060.4 | S19: =H19*$R$31 -> 271542.86 | T19: =SUMPRODUCT(D19:H19, N$32:R$32)*0.01 -> 754.86986 | U19: =IFERROR(S19/I19,0) -> 0.1 | V19: =0.1*I19 -> 271542.86 | W19: =SUMPRODUCT($N$31:$Q$31,D19:G19) -> 2443885.7 | Y19: =K19-0.1*J19 -> 0
... A26: October - Weekend Off-peak | B26: 120 | C26: =B26*1000 -> 120000 | D26: 0 | E26: 0 | F26: 45341.108 | G26: 0 | H26: 6857.1429 | I26: =SUMPRODUCT(D26:H26, N$31:R$31) -> 1234285.7 | J26: =(SUMPRODUCT(D26:H26, N$31:R$31)*0.35)/3.6 -> 120000 | K26: =($R$31*H26*0.35)/3.6 -> 12000 | L26: =VLOOKUP(A26,F48:G69,2,FALSE) -> 30.1 | M26: =L26*J26 -> 3612000 | N26: =45*($R$31*H26*0.35)/3.6 -> 540000 | O26: =SUMPRODUCT(D26:H26, N$31:R$31)*0.35*0.65/3.6 -> 78000 | P26: =SUMPRODUCT(D26:H26, N$30:R$30) -> 2491792 | Q26: =J26*0.8*0.87*15 -> 1252800 | R26: =IFERROR(M26+N26-O26-P26-Q26,0) -> 329408.05 | S26: =H26*$R$31 -> 123428.57 | T26: =SUMPRODUCT(D26:H26, N$32:R$32)*0.01 -> 159.37959 | U26: =IFERROR(S26/I26,0) -> 0.1 | V26: =0.1*I26 -> 123428.57 | W26: =SUMPRODUCT($N$31:$Q$31,D26:G26) -> 1110857.1 | Y26: =K26-0.1*J26 -> 0
A27: Total | C27: =SUM(C7:C26) -> 3672000 | D27: =SUM(D7:D26) -> 490653.68 | E27: =SUM(E7:E26) -> 0 | F27: =SUM(F7:F26) -> 484765.64 | G27: =SUM(G7:G26) -> 30038.676 | H27: =SUM(H7:H26) -> 156342.86 | J27: =SUM(J7:J26) -> 2736000 | K27: =SUM(K7:K26) -> 273600 | L27: =SUM(L7:L26) -> 650.15 | M27: =SUM(M7:M26) -> 95597400 | N27: =SUM(N7:N26) -> 12312000 | O27: =SUM(O7:O26) -> 1778400 | P27: =SUM(P7:P26) -> 54909992 | Q27: =SUM(Q7:Q26) -> 28563840 | ... T27: =SUM(T7:T26) -> 9000 | V27: =SUM(V7:V26) -> 2814171.4 | W27: =SUMPRODUCT($N$31:$Q$31,D27:G27) -> 25327543
F29: Period | G29: Electricity_Forward_Price | J29: Scalars | K29: Value | M29: Fuel | N29: Stockpile coal | O29: Colombian coal | P29: Russian coal | Q29: Scottish coal | R29: Wood chips
F30: June - Weekday Peak | G30: 36 | J30: Efficiency | K30: 0.35 | M30: Price_per_t | N30: 42.56 | O30: 43.93 | P30: 43.8 | Q30: 42 | R30: 73.77
F31: June - Weekday Off-peak | G31: 27 | J31: Plant_Capacity_MW | K31: 1000 | M31: CV_GJ_per_t | N31: 25.81 | O31: 25.12 | P31: 24.5 | Q31: 26.2 | R31: 18
F32: June - Weekend Peak | G32: 33.5 | J32: Grid_Charge_per_MWh | K32: 0.65 | M32: SO2_percent | N32: 1.38 | O32: 0.7 | P32: 0.35 | Q32: 1.72 | R32: 0.01
F33: June - Weekend Off-peak | G33: 26.2 | J33: CO2_Intensity_t_per_MWh | K33: 0.8
F34: July - Weekday Peak | G34: 36.35 | J34: CO2_Cost_EUR_per_t | K34: 15
F35: July - Weekday Off-peak | G35: 27 | J35: FX_EUR_per_GBP | K35: 0.87
F36: July - Weekend Peak | G36: 34.3 | J36: ROC_per_MWh | K36: 45
F37: July - Weekend Off-peak | G37: 26.3 | J37: Sulphur_Allowance_t | K37: 9000
F38: August - Weekday Peak | G38: 37.65 | J38: Stockpile_Tonnes | K38: 600000
F39: August - Weekday Off-peak | G39: 28.2 | J39: Biomass_Share_Max | K39: 0.1
F40: August - Weekend Peak | G40: 35.65 | J40: Hours_Peak_per_Day | K40: 12
F41: August - Weekend Off-peak | G41: 27.5 | J41: Hours_Offpeak_per_Day | K41: 12
F42: September - Weekday Peak | G42: 38.35 | J42: P_Colombian_t | K42: 0
F43: September - Weekday Off-peak | G43: 28.5 | J43: P_Russian_t | K43: 0
F44: September - Weekend Peak | G44: 35.8 | J44: P_Scottish_t | K44: 0
F45: September - Weekend Off-peak | G45: 27.65
F46: October - Weekday Peak | G46: 43.7
F47: October - Weekday Off-peak | G47: 31.7
F48: October - Weekend Peak | G48: 38.7
F49: October - Weekend Off-peak | G49: 30.1

Sheet Sensitivity Report 1
A1: Microsoft Excel 16.102 Sensitivity Report
A2: Worksheet: [GROUP_I_IC.xlsx]Final
A3: Report Created: 11/13/25 22:52:19
A6: Variable Cells
D7: Final | E7: Reduced | F7: Objective | G7: Allowable | H7: Allowable
B8: Cell | C8: Name | D8: Value | E8: Cost | F8: Coefficient | G8: Increase | H8: Decrease
B9: $D$7 | C9: June - Weekday Peak X_Stockpile_t | D9: 94687.552 | E9: 0 | F9: 19.946801 | G9: 54.611679 | H9: 0.054620564
B10: $E$7 | C10: June - Weekday Peak X_Colombian_t | D10: 0 | E10: -0.19517996 | F10: 16.905756 | G10: 0.19517996 | H10: 1e+30
B11: $F$7 | C11: June - Weekday Peak X_Russian_t | D11: 0 | E11: 0.051848269 | F11: 15.534236 | G11: 0.051848269 | H11: 1e+30
B12: $G$7 | C12: June - Weekday Peak X_Scottish_t | D12: 0 | E12: 0.055445904 | F12: 21.451306 | G12: 0.055445904 | H12: 1e+30
B13: $H$7 | C13: June - Weekday Peak X_Wood_t | D13: 15085.714 | E13: 0 | F13: 48.5725 | G13: 1e+30 | H13: 38.086409
B14: $D$8 | C14: June - Weekday Off-peak X_Stockpile_t | D14: 0 | E14: -2.3758396 | F14: -2.6369486 | G14: 2.3758396 | H14: 1e+30
B15: $E$8 | C15: June - Weekday Off-peak X_Colombian_t | D15: 0 | E15: -2.5075043 | F15: -5.0742444 | G15: 2.5075043 | H15: 1e+30
B16: $F$8 | C16: June - Weekday Off-peak X_Russian_t | D16: 0 | E16: -2.2034044 | F16: -5.9032639 | G16: 2.2034044 | H16: 1e+30
B17: $G$8 | C17: June - Weekday Off-peak X_Scottish_t | D17: 0 | E17: -2.3562937 | F17: -1.4736944 | G17: 2.3562937 | H17: 1e+30
B18: $H$8 | C18: June - Weekday Off-peak X_Wood_t | D18: 0 | E18: 0 | F18: 32.8225 | G18: 14.569449 | H18: 32.78654
B19: $D$9 | C19: June - Weekend Peak X_Stockpile_t | D19: 34431.837 | E19: 0 | F19: 13.673537 | G19: 54.611679 | H19: 0.054620564
B20: $E$9 | C20: June - Weekend Peak X_Colombian_t | D20: 0 | E20: -0.19517996 | F20: 10.8002 | G20: 0.19517996 | H20: 1e+30
... B108: $H$26 | C108: October - Weekend Off-peak X_Wood_t | D108: 6857.1429 | E108: 0 | F108: 38.2475 | G108: 1e+30 | H108: 38.048317
A110: Constraints
D111: Final | E111: Shadow | F111: Constraint | G111: Allowable | H111: Allowable
B112: Cell | C112: Name | D112: Value | E112: Price | F112: R.H. Side | G112: Increase | H112: Decrease
B113: $D$27 | C113: Total X_Stockpile_t | D113: 490653.68 | E113: 0 | F113: 600000 | G113: 1e+30 | H113: 109346.32
B114: $J$7 | C114: June - Weekday Peak Total_MWh | D114: 264000 | E114: 8.1478695 | F114: 264000 | G114: 81576.393 | H114: 171740.01
B115: $J$8 | C115: June - Weekday Off-peak Total_MWh | D115: 0 | E115: 0 | F115: 264000 | G115: 1e+30 | H115: 264000
B116: $J$9 | C116: June - Weekend Peak Total_MWh | D116: 96000 | E116: 5.6478695 | F116: 96000 | G116: 81576.393 | H116: 96000
B117: $J$10 | C117: June - Weekend Off-peak Total_MWh | D117: 0 | E117: 0 | F117: 96000 | G117: 1e+30 | H117: 96000
B118: $J$11 | C118: July - Weekday Peak Total_MWh | D118: 264000 | E118: 8.4978695 | F118: 264000 | G118: 81576.393 | H118: 171740.01
B119: $J$12 | C119: July - Weekday Off-peak Total_MWh | D119: 0 | E119: 0 | F119: 264000 | G119: 1e+30 | H119: 264000
B120: $J$13 | C120: July - Weekend Peak Total_MWh | D120: 108000 | E120: 6.4478695 | F120: 108000 | G120: 81576.393 | H120: 108000
B121: $J$14 | C121: July - Weekend Off-peak Total_MWh | D121: 0 | E121: 0 | F121: 108000 | G121: 1e+30 | H121: 108000
B122: $J$15 | C122: August - Weekday Peak Total_MWh | D122: 264000 | E122: 9.7978695 | F122: 264000 | G122: 81576.393 | H122: 171740.01
B123: $J$16 | C123: August - Weekday Off-peak Total_MWh | D123: 264000 | E123: 0.34786955 | F123: 264000 | G123: 81576.393 | H123: 171740.01
B124: $J$17 | C124: August - Weekend Peak Total_MWh | D124: 108000 | E124: 7.7978695 | F124: 108000 | G124: 81576.393 | H124: 108000
... B154: $Y$26 | C154: October - Weekend Off-peak Wood_Chips_Constraint | D154: 0 | E154: 21.741895 | F154: 0 | G154: 108000 | H154: 12000

Sheet Answer Report 1
A1: Microsoft Excel 16.102 Answer Report
A2: Worksheet: [GROUP_I_IC.xlsx]Final
A3: Report Created: 11/13/25 22:52:17
A4: Result: Solver found a solution. All constraints and optimality conditions are satisfied.
A5: Solver Engine
B6: Engine: Simplex LP
B7: Solution Time: 38655078.443 Seconds.
B8: Iterations: 39 Subproblems: 0
A9: Solver Options
B10: Max Time Unlimited, Iterations Unlimited, Precision 0.000001
B11: Max Subproblems Unlimited, Max Integer Sols Unlimited, Integer Tolerance 1%, Solve Without Integer Constraints, Assume NonNegative
A14: Objective Cell (Max)
B15: Cell | C15: Name | D15: Original Value | E15: Final Value
B16: $R$27 | C16: Total Profit | D16: 22657168 | E16: 22657168
A19: Variable Cells
B20: Cell | C20: Name | D20: Original Value | E20: Final Value | F20: Integer
B21: $D$7 | C21: June - Weekday Peak X_Stockpile_t | D21: 94687.552 | E21: 94687.552 | F21: Contin
B22: $E$7 | C22: June - Weekday Peak X_Colombian_t | D22: 0 | E22: 0 | F22: Contin
B23: $F$7 | C23: June - Weekday Peak X_Russian_t | D23: 0 | E23: 0 | F23: Contin
B24: $G$7 | C24: June - Weekday Peak X_Scottish_t | D24: 0 | E24: 0 | F24: Contin
B25: $H$7 | C25: June - Weekday Peak X_Wood_t | D25: 15085.714 | E25: 15085.714 | F25: Contin
B26: $D$8 | C26: June - Weekday Off-peak X_Stockpile_t | D26: 0 | E26: 0 | F26: Contin
B27: $E$8 | C27: June - Weekday Off-peak X_Colombian_t | D27: 0 | E27: 0 | F27: Contin
B28: $F$8 | C28: June - Weekday Off-peak X_Russian_t | D28: 0 | E28: 0 | F28: Contin
B29: $G$8 | C29: June - Weekday Off-peak X_Scottish_t | D29: 0 | E29: 0 | F29: Contin
B30: $H$8 | C30: June - Weekday Off-peak X_Wood_t | D30: 0 | E30: 0 | F30: Contin
B31: $D$9 | C31: June - Weekend Peak X_Stockpile_t | D31: 34431.837 | E31: 34431.837 | F31: Contin
B32: $E$9 | C32: June - Weekend Peak X_Colombian_t | D32: 0 | E32: 0 | F32: Contin
... B120: $H$26 | C120: October - Weekend Off-peak X_Wood_t | D120: 6857.1429 | E120: 6857.1429 | F120: Contin
A123: Constraints
B124: Cell | C124: Name | D124: Cell Value | E124: Formula | F124: Status | G124: Slack
B125: $D$27 | C125: Total X_Stockpile_t | D125: 490653.68 | E125: $D$27<=$K$38 | F125: Not Binding | G125: 109346.32
B126: $J$7 | C126: June - Weekday Peak Total_MWh | D126: 264000 | E126: $J$7<=$C$7 | F126: Binding | G126: 0
B127: $J$8 | C127: June - Weekday Off-peak Total_MWh | D127: 0 | E127: $J$8<=$C$8 | F127: Not Binding | G127: 264000
B128: $J$9 | C128: June - Weekend Peak Total_MWh | D128: 96000 | E128: $J$9<=$C$9 | F128: Binding | G128: 0
B129: $J$10 | C129: June - Weekend Off-peak Total_MWh | D129: 0 | E129: $J$10<=$C$10 | F129: Not Binding | G129: 96000
B130: $J$11 | C130: July - Weekday Peak Total_MWh | D130: 264000 | E130: $J$11<=$C$11 | F130: Binding | G130: 0
B131: $J$12 | C131: July - Weekday Off-peak Total_MWh | D131: 0 | E131: $J$12<=$C$12 | F131: Not Binding | G131: 264000
B132: $J$13 | C132: July - Weekend Peak Total_MWh | D132: 108000 | E132: $J$13<=$C$13 | F132: Binding | G132: 0
B133: $J$14 | C133: July - Weekend Off-peak Total_MWh | D133: 0 | E133: $J$14<=$C$14 | F133: Not Binding | G133: 108000
...

Sheet CO2 20€
A6: Month | B6: Hours | C6: Max_Capacity | D6: X_Stockpile_t | E6: X_Colombian_t | F6: X_Russian_t | G6: X_Scottish_t | H6: X_Wood_t | I6: Thermal_Input_GJ | J6: Total_MWh | K6: Wood_Chips_MWh | L6: Price_per MWh | M6: Revenue | N6: ROC_Revenue | O6: Grid_Charge | P6: Fuel_Cost | Q6: CO2_Cost | R6: Profit | S6: Wood_Thermal_GJ | T6: SO2_tonnes | U6: Biomass_share | V6: Thermal_Input_GJ*0.1 | W6: Coal fule | Y6: Wood_Chips_Constraint
A7: June - Weekday Peak | B7: 264 | C7: =B7*1000 -> 264000 | D7: 94687.552 | E7: 0 | F7: 0 | G7: 0 | H7: 15085.714 | I7: =SUMPRODUCT(D7:H7, N$31:R$31) -> 2715428.6 | J7: =(SUMPRODUCT(D7:H7, N$31:R$31)*0.35)/3.6 -> 264000 | K7: =($R$31*H7*0.35)/3.6 -> 26400 | L7: =VLOOKUP(A7,F29:G49,2,FALSE) -> 36 | M7: =L7*J7 -> 9504000 | N7: =45*($R$31*H7*0.35)/3.6 -> 1188000 | O7: =SUMPRODUCT(D7:H7, N$31:R$31)*0.35*0.65/3.6 -> 171600 | P7: =SUMPRODUCT(D7:H7, N$30:R$30) -> 5142775.4 | Q7: =J7*0.8*0.87*20 -> 3674880 | R7: =IFERROR(M7+N7-O7-P7-Q7,0) -> 1702744.6 | S7: =H7*$R$31 -> 271542.86 | T7: =SUMPRODUCT(D7:H7, N$32:R$32)*0.01 -> 1308.1968 | U7: =IFERROR(S7/I7,0) -> 0.1 | V7: =0.1*I7 -> 271542.86 | W7: =SUMPRODUCT($N$31:$Q$31,D7:G7) -> 2443885.7 | Y7: =K7-0.1*J7 -> 0
A8: June - Weekday Off-peak | B8: 264 | C8: =B8*1000 -> 264000 | D8: 0 | E8: 0 | F8: 0 | G8: 0 | H8: 0 | I8: =SUMPRODUCT(D8:H8, N$31:R$31) -> 0 | J8: =(SUMPRODUCT(D8:H8, N$31:R$31)*0.35)/3.6 -> 0 | K8: =($R$31*H8*0.35)/3.6 -> 0 | L8: =VLOOKUP(A8,F30:G51,2,FALSE) -> 27 | M8: =L8*J8 -> 0 | N8: =45*($R$31*H8*0.35)/3.6 -> 0 | O8: =SUMPRODUCT(D8:H8, N$31:R$31)*0.35*0.65/3.6 -> 0 | P8: =SUMPRODUCT(D8:H8, N$30:R$30) -> 0 | Q8: =J8*0.8*0.87*20 -> 0 | R8: =IFERROR(M8+N8-O8-P8-Q8,0) -> 0 | S8: =H8*$R$31 -> 0 | T8: =SUMPRODUCT(D8:H8, N$32:R$32)*0.01 -> 0 | U8: =IFERROR(S8/I8,0) -> 0 | V8: =0.1*I8 -> 0 | W8: =SUMPRODUCT($N$31:$Q$31,D8:G8) -> 0 | Y8: =K8-0.1*J8 -> 0
A9: June - Weekend Peak | B9: 96 | C9: =B9*1000 -> 96000 | D9: 34431.837 | E9: 0 | F9: 0 | G9: 0 | H9: 5485.7143 | I9: =SUMPRODUCT(D9:H9, N$31:R$31) -> 987428.57 | J9: =(SUMPRODUCT(D9:H9, N$31:R$31)*0.35)/3.6 -> 96000 | K9: =($R$31*H9*0.35)/3.6 -> 9600 | L9: =VLOOKUP(A9,F31:G52,2,FALSE) -> 33.5 | M9: =L9*J9 -> 3216000 | N9: =45*($R$31*H9*0.35)/3.6 -> 432000 | O9: =SUMPRODUCT(D9:H9, N$31:R$31)*0.35*0.65/3.6 -> 62400 | P9: =SUMPRODUCT(D9:H9, N$30:R$30) -> 1870100.1 | Q9: =J9*0.8*0.87*20 -> 1336320 | R9: =IFERROR(M9+N9-O9-P9-Q9,0) -> 379179.87 | S9: =H9*$R$31 -> 98742.857 | T9: =SUMPRODUCT(D9:H9, N$32:R$32)*0.01 -> 475.70792 | U9: =IFERROR(S9/I9,0) -> 0.1 | V9: =0.1*I9 -> 98742.857 | W9: =SUMPRODUCT($N$31:$Q$31,D9:G9) -> 888685.71 | Y9: =K9-0.1*J9 -> 0
A10: June - Weekend Off-peak | B10: 96 | C10: =B10*1000 -> 96000 | D10: 0 | E10: 0 | F10: 0 | G10: 0 | H10: 0 | I10: =SUMPRODUCT(D10:H10, N$31:R$31) -> 0 | J10: =(SUMPRODUCT(D10:H10, N$31:R$31)*0.35)/3.6 -> 0 | K10: =($R$31*H10*0.35)/3.6 -> 0 | L10: =VLOOKUP(A10,F32:G53,2,FALSE) -> 26.2 | M10: =L10*J10 -> 0 | N10: =45*($R$31*H10*0.35)/3.6 -> 0 | O10: =SUMPRODUCT(D10:H10, N$31:R$31)*0.35*0.65/3.6 -> 0 | P10: =SUMPRODUCT(D10:H10, N$30:R$30) -> 0 | Q10: =J10*0.8*0.87*20 -> 0 | R10: =IFERROR(M10+N10-O10-P10-Q10,0) -> 0 | S10: =H10*$R$31 -> 0 | T10: =SUMPRODUCT(D10:H10, N$32:R$32)*0.01 -> 0 | U10: =IFERROR(S10/I10,0) -> 0 | V10: =0.1*I10 -> 0 | W10: =SUMPRODUCT($N$31:$Q$31,D10:G10) -> 0 | Y10: =K10-0.1*J10 -> 0
A11: July - Weekday Peak | B11: 264 | C11: =B11*1000 -> 264000 | D11: 94687.552 | E11: 0 | F11: 0 | G11: 0 | H11: 15085.714 | I11: =SUMPRODUCT(D11:H11, N$31:R$31) -> 2715428.6 | J11: =(SUMPRODUCT(D11:H11, N$31:R$31)*0.35)/3.6 -> 264000 | K11: =($R$31*H11*0.35)/3.6 -> 26400 | L11: =VLOOKUP(A11,F33:G54,2,FALSE) -> 36.35 | M11: =L11*J11 -> 9596400 | N11: =45*($R$31*H11*0.35)/3.6 -> 1188000 | O11: =SUMPRODUCT(D11:H11, N$31:R$31)*0.35*0.65/3.6 -> 171600 | P11: =SUMPRODUCT(D11:H11, N$30:R$30) -> 5142775.4 | Q11: =J11*0.8*0.87*20 -> 3674880 | R11: =IFERROR(M11+N11-O11-P11-Q11,0) -> 1795144.6 | S11: =H11*$R$31 -> 271542.86 | T11: =SUMPRODUCT(D11:H11, N$32:R$32)*0.01 -> 1308.1968 | U11: =IFERROR(S11/I11,0) -> 0.1 | V11: =0.1*I11 -> 271542.86 | W11: =SUMPRODUCT($N$31:$Q$31,D11:G11) -> 2443885.7 | Y11: =K11-0.1*J11 -> 0
A12: July - Weekday Off-peak | B12: 264 | C12: =B12*1000 -> 264000 | D12: 0 | E12: 0 | F12: 0 | G12: 0 | H12: 0 | I12: =SUMPRODUCT(D12:H12, N$31:R$31) -> 0 | J12: =(SUMPRODUCT(D12:H12, N$31:R$31)*0.35)/3.6 -> 0 | K12: =($R$31*H12*0.35)/3.6 -> 0 | L12: =VLOOKUP(A12,F34:G55,2,FALSE) -> 27 | M12: =L12*J12 -> 0 | N12: =45*($R$31*H12*0.35)/3.6 -> 0 | O12: =SUMPRODUCT(D12:H12, N$31:R$31)*0.35*0.65/3.6 -> 0 | P12: =SUMPRODUCT(D12:H12, N$30:R$30) -> 0 | Q12: =J12*0.8*0.87*20 -> 0 | R12: =IFERROR(M12+N12-O12-P12-Q12,0) -> 0 | S12: =H12*$R$31 -> 0 | T12: =SUMPRODUCT(D12:H12, N$32:R$32)*0.01 -> 0 | U12: =IFERROR(S12/I12,0) -> 0 | V12: =0.1*I12 -> 0 | W12: =SUMPRODUCT($N$31:$Q$31,D12:G12) -> 0 | Y12: =K12-0.1*J12 -> 0
A13: July - Weekend Peak | B13: 108 | C13: =B13*1000 -> 108000 | D13: 38735.817 | E13: 0 | F13: 0 | G13: 0 | H13: 6171.4286 | I13: =SUMPRODUCT(D13:H13, N$31:R$31) -> 1110857.1 | J13: =(SUMPRODUCT(D13:H13, N$31:R$31)*0.35)/3.6 -> 108000 | K13: =($R$31*H13*0.35)/3.6 -> 10800 | L13: =VLOOKUP(A13,F35:G56,2,FALSE) -> 34.3 | M13: =L13*J13 -> 3704400 | N13: =45*($R$31*H13*0.35)/3.6 -> 486000 | O13: =SUMPRODUCT(D13:H13, N$31:R$31)*0.35*0.65/3.6 -> 70200 | P13: =SUMPRODUCT(D13:H13, N$30:R$30) -> 2103862.6 | Q13: =J13*0.8*0.87*20 -> 1503360 | R13: =IFERROR(M13+N13-O13-P13-Q13,0) -> 512977.36 | S13: =H13*$R$31 -> 111085.71 | T13: =SUMPRODUCT(D13:H13, N$32:R$32)*0.01 -> 535.17141 | U13: =IFERROR(S13/I13,0) -> 0.1 | V13: =0.1*I13 -> 111085.71 | W13: =SUMPRODUCT($N$31:$Q$31,D13:G13) -> 999771.43 | Y13: =K13-0.1*J13 -> 0
A14: July - Weekend Off-peak | B14: 108 | C14: =B14*1000 -> 108000 | D14: 0 | E14: 0 | F14: 0 | G14: 0 | H14: 0 | I14: =SUMPRODUCT(D14:H14, N$31:R$31) -> 0 | J14: =(SUMPRODUCT(D14:H14, N$31:R$31)*0.35)/3.6 -> 0 | K14: =($R$31*H14*0.35)/3.6 -> 0 | L14: =VLOOKUP(A14,F36:G57,2,FALSE) -> 26.3 | M14: =L14*J14 -> 0 | N14: =45*($R$31*H14*0.35)/3.6 -> 0 | O14: =SUMPRODUCT(D14:H14, N$31:R$31)*0.35*0.65/3.6 -> 0 | P14: =SUMPRODUCT(D14:H14, N$30:R$30) -> 0 | Q14: =J14*0.8*0.87*20 -> 0 | R14: =IFERROR(M14+N14-O14-P14-Q14,0) -> 0 | S14: =H14*$R$31 -> 0 | T14: =SUMPRODUCT(D14:H14, N$32:R$32)*0.01 -> 0 | U14: =IFERROR(S14/I14,0) -> 0 | V14: =0.1*I14 -> 0 | W14: =SUMPRODUCT($N$31:$Q$31,D14:G14) -> 0 | Y14: =K14-0.1*J14 -> 0
A15: August - Weekday Peak | B15: 264 | C15: =B15*1000 -> 264000 | D15: 94687.552 | E15: 0 | F15: 0 | G15: 0 | H15: 15085.714 | I15: =SUMPRODUCT(D15:H15, N$31:R$31) -> 2715428.6 | J15: =(SUMPRODUCT(D15:H15, N$31:R$31)*0.35)/3.6 -> 264000 | K15: =($R$31*H15*0.35)/3.6 -> 26400 | L15: =VLOOKUP(A15,F37:G58,2,FALSE) -> 37.65 | M15: =L15*J15 -> 9939600 | N15: =45*($R$31*H15*0.35)/3.6 -> 1188000 | O15: =SUMPRODUCT(D15:H15, N$31:R$31)*0.35*0.65/3.6 -> 171600 | P15: =SUMPRODUCT(D15:H15, N$30:R$30) -> 5142775.4 | Q15: =J15*0.8*0.87*20 -> 3674880 | R15: =IFERROR(M15+N15-O15-P15-Q15,0) -> 2138344.6 | S15: =H15*$R$31 -> 271542.86 | T15: =SUMPRODUCT(D15:H15, N$32:R$32)*0.01 -> 1308.1968 | U15: =IFERROR(S15/I15,0) -> 0.1 | V15: =0.1*I15 -> 271542.86 | W15: =SUMPRODUCT($N$31:$Q$31,D15:G15) -> 2443885.7 | Y15: =K15-0.1*J15 -> 0
A16: August - Weekday Off-peak | B16: 264 | C16: =B16*1000 -> 264000 | D16: 0 | E16: 0 | F16: 0 | G16: 0 | H16: 0 | I16: =SUMPRODUCT(D16:H16, N$31:R$31) -> 0 | J16: =(SUMPRODUCT(D16:H16, N$31:R$31)*0.35)/3.6 -> 0 | K16: =($R$31*H16*0.35)/3.6 -> 0 | L16: =VLOOKUP(A16,F38:G59,2,FALSE) -> 28.2 | M16: =L16*J16 -> 0 | N16: =45*($R$31*H16*0.35)/3.6 -> 0 | O16: =SUMPRODUCT(D16:H16, N$31:R$31)*0.35*0.65/3.6 -> 0 | P16: =SUMPRODUCT(D16:H16, N$30:R$30) -> 0 | Q16: =J16*0.8*0.87*20 -> 0 | R16: =IFERROR(M16+N16-O16-P16-Q16,0) -> 0 | S16: =H16*$R$31 -> 0 | T16: =SUMPRODUCT(D16:H16, N$32:R$32)*0.01 -> 0 | U16: =IFERROR(S16/I16,0) -> 0 | V16: =0.1*I16 -> 0 | W16: =SUMPRODUCT($N$31:$Q$31,D16:G16) -> 0 | Y16: =K16-0.1*J16 -> 0
A17: August - Weekend Peak | B17: 108 | C17: =B17*1000 -> 108000 | D17: 38735.817 | E17: 0 | F17: 0 | G17: 0 | H17: 6171.4286 | I17: =SUMPRODUCT(D17:H17, N$31:R$31) -> 1110857.1 | J17: =(SUMPRODUCT(D17:H17, N$31:R$31)*0.35)/3.6 -> 108000 | K17: =($R$31*H17*0.35)/3.6 -> 10800 | L17: =VLOOKUP(A17,F39:G60,2,FALSE) -> 35.65 | M17: =L17*J17 -> 3850200 | N17: =45*($R$31*H17*0.35)/3.6 -> 486000 | O17: =SUMPRODUCT(D17:H17, N$31:R$31)*0.35*0.65/3.6 -> 70200 | P17: =SUMPRODUCT(D17:H17, N$30:R$30) -> 2103862.6 | Q17: =J17*0.8*0.87*20 -> 1503360 | R17: =IFERROR(M17+N17-O17-P17-Q17,0) -> 658777.36 | S17: =H17*$R$31 -> 111085.71 | T17: =SUMPRODUCT(D17:H17, N$32:R$32)*0.01 -> 535.17141 | U17: =IFERROR(S17/I17,0) -> 0.1 | V17: =0.1*I17 -> 111085.71 | W17: =SUMPRODUCT($N$31:$Q$31,D17:G17) -> 999771.43 | Y17: =K17-0.1*J17 -> 0
A18: August - Weekend Off-peak | B18: 108 | C18: =B18*1000 -> 108000 | D18: 0 | E18: 0 | F18: 0 | G18: 0 | H18: 0 | I18: =SUMPRODUCT(D18:H18, N$31:R$31) -> 0 | J18: =(SUMPRODUCT(D18:H18, N$31:R$31)*0.35)/3.6 -> 0 | K18: =($R$31*H18*0.35)/3.6 -> 0 | L18: =VLOOKUP(A18,F40:G61,2,FALSE) -> 27.5 | M18: =L18*J18 -> 0 | N18: =45*($R$31*H18*0.35)/3.6 -> 0 | O18: =SUMPRODUCT(D18:H18, N$31:R$31)*0.35*0.65/3.6 -> 0 | P18: =SUMPRODUCT(D18:H18, N$30:R$30) -> 0 | Q18: =J18*0.8*0.87*20 -> 0 | R18: =IFERROR(M18+N18-O18-P18-Q18,0) -> 0 | S18: =H18*$R$31 -> 0 | T18: =SUMPRODUCT(D18:H18, N$32:R$32)*0.01 -> 0 | U18: =IFERROR(S18/I18,0) -> 0 | V18: =0.1*I18 -> 0 | W18: =SUMPRODUCT($N$31:$Q$31,D18:G18) -> 0 | Y18: =K18-0.1*J18 -> 0
A19: September - Weekday Peak | B19: 264 | C19: =B19*1000 -> 264000 | D19: 0 | E19: 0 | F19: 18357.448 | G19: 76111.765 | H19: 15085.714 | I19: =SUMPRODUCT(D19:H19, N$31:R$31) -> 2715428.6 | J19: =(SUMPRODUCT(D19:H19, N$31:R$31)*0.35)/3.6 -> 264000 | K19: =($R$31*H19*0.35)/3.6 -> 26400 | L19: =VLOOKUP(A19,F41:G62,2,FALSE) -> 38.35 | M19: =L19*J19 -> 10124400 | N19: =45*($R$31*H19*0.35)/3.6 -> 1188000 | O19: =SUMPRODUCT(D19:H19, N$31:R$31)*0.35*0.65/3.6 -> 171600 | P19: =SUMPRODUCT(D19:H19, N$30:R$30) -> 5113623.5 | Q19: =J19*0.8*0.87*20 -> 3674880 | R19: =IFERROR(M19+N19-O19-P19-Q19,0) -> 2352296.5 | S19: =H19*$R$31 -> 271542.86 | T19: =SUMPRODUCT(D19:H19, N$32:R$32)*0.01 -> 1374.882 | U19: =IFERROR(S19/I19,0) -> 0.1 | V19: =0.1*I19 -> 271542.86 | W19: =SUMPRODUCT($N$31:$Q$31,D19:G19) -> 2443885.7 | Y19: =K19-0.1*J19 -> 0
... A26: October - Weekend Off-peak | B26: 120 | C26: =B26*1000 -> 120000 | D26: 0 | E26: 0 | F26: 0 | G26: 0 | H26: 0 | I26: =SUMPRODUCT(D26:H26, N$31:R$31) -> 0 | J26: =(SUMPRODUCT(D26:H26, N$31:R$31)*0.35)/3.6 -> 0 | K26: =($R$31*H26*0.35)/3.6 -> 0 | L26: =VLOOKUP(A26,F48:G69,2,FALSE) -> 30.1 | M26: =L26*J26 -> 0 | N26: =45*($R$31*H26*0.35)/3.6 -> 0 | O26: =SUMPRODUCT(D26:H26, N$31:R$31)*0.35*0.65/3.6 -> 0 | P26: =SUMPRODUCT(D26:H26, N$30:R$30) -> 0 | Q26: =J26*0.8*0.87*20 -> 0 | R26: =IFERROR(M26+N26-O26-P26-Q26,0) -> 0 | S26: =H26*$R$31 -> 0 | T26: =SUMPRODUCT(D26:H26, N$32:R$32)*0.01 -> 0 | U26: =IFERROR(S26/I26,0) -> 0 | V26: =0.1*I26 -> 0 | W26: =SUMPRODUCT($N$31:$Q$31,D26:G26) -> 0 | Y26: =K26-0.1*J26 -> 0
A27: Total | C27: =SUM(C7:C26) -> 3672000 | D27: =SUM(D7:D26) -> 395966.13 | E27: =SUM(E7:E26) -> 0 | F27: =SUM(F7:F26) -> 195187.77 | G27: =SUM(G7:G26) -> 165149.93 | H27: =SUM(H7:H26) -> 119314.29 | J27: =SUM(J7:J26) -> 2088000 | K27: =SUM(K7:K26) -> 208800 | L27: =SUM(L7:L26) -> 650.15 | M27: =SUM(M7:M26) -> 77016600 | N27: =SUM(N7:N26) -> 9396000 | O27: =SUM(O7:O26) -> 1357200 | P27: =SUM(P7:P26) -> 41139655 | Q27: =SUM(Q7:Q26) -> 29064960 | ... T27: =SUM(T7:T26) -> 9000 | V27: =SUM(V7:V26) -> 2147657.1 | W27: =SUMPRODUCT($N$31:$Q$31,D27:G27) -> 19328914
F29: Period | G29: Electricity_Forward_Price | J29: Scalars | K29: Value | M29: Fuel | N29: Stockpile coal | O29: Colombian coal | P29: Russian coal | Q29: Scottish coal | R29: Wood chips
F30: June - Weekday Peak | G30: 36 | J30: Efficiency | K30: 0.35 | M30: Price_per_t | N30: 42.56 | O30: 43.93 | P30: 43.8 | Q30: 42 | R30: 73.77
F31: June - Weekday Off-peak | G31: 27 | J31: Plant_Capacity_MW | K31: 1000 | M31: CV_GJ_per_t | N31: 25.81 | O31: 25.12 | P31: 24.5 | Q31: 26.2 | R31: 18
F32: June - Weekend Peak | G32: 33.5 | J32: Grid_Charge_per_MWh | K32: 0.65 | M32: SO2_percent | N32: 1.38 | O32: 0.7 | P32: 0.35 | Q32: 1.72 | R32: 0.01
F33: June - Weekend Off-peak | G33: 26.2 | J33: CO2_Intensity_t_per_MWh | K33: 0.8
F34: July - Weekday Peak | G34: 36.35 | J34: CO2_Cost_EUR_per_t | K34: 15
F35: July - Weekday Off-peak | G35: 27 | J35: FX_EUR_per_GBP | K35: 0.87
F36: July - Weekend Peak | G36: 34.3 | J36: ROC_per_MWh | K36: 45
F37: July - Weekend Off-peak | G37: 26.3 | J37: Sulphur_Allowance_t | K37: 9000
F38: August - Weekday Peak | G38: 37.65 | J38: Stockpile_Tonnes | K38: 600000
F39: August - Weekday Off-peak | G39: 28.2 | J39: Biomass_Share_Max | K39: 0.1
F40: August - Weekend Peak | G40: 35.65 | J40: Hours_Peak_per_Day | K40: 12
F41: August - Weekend Off-peak | G41: 27.5 | J41: Hours_Offpeak_per_Day | K41: 12
F42: September - Weekday Peak | G42: 38.35 | J42: P_Colombian_t | K42: 0
F43: September - Weekday Off-peak | G43: 28.5 | J43: P_Russian_t | K43: 0
F44: September - Weekend Peak | G44: 35.8 | J44: P_Scottish_t | K44: 0
F45: September - Weekend Off-peak | G45: 27.65
F46: October - Weekday Peak | G46: 43.7
F47: October - Weekday Off-peak | G47: 31.7
F48: October - Weekend Peak | G48: 38.7
F49: October - Weekend Off-peak | G49: 30.1

Sheet CO2 30€
A6: Month | B6: Hours | C6: Max_Capacity | D6: X_Stockpile_t | E6: X_Colombian_t | F6: X_Russian_t | G6: X_Scottish_t | H6: X_Wood_t | I6: Thermal_Input_GJ | J6: Total_MWh | K6: Wood_Chips_MWh | L6: Price_per MWh | M6: Revenue | N6: ROC_Revenue | O6: Grid_Charge | P6: Fuel_Cost | Q6: CO2_Cost | R6: Profit | S6: Wood_Thermal_GJ | T6: SO2_tonnes | U6: Biomass_share | V6: Thermal_Input_GJ*0.1 | W6: Coal fule | Y6: Wood_Chips_Constraint
A7: June - Weekday Peak | B7: 264 | C7: =B7*1000 -> 264000 | D7: 0 | E7: 0 | F7: 0 | G7: 0 | H7: 0 | I7: =SUMPRODUCT(D7:H7, N$31:R$31) -> 0 | J7: =(SUMPRODUCT(D7:H7, N$31:R$31)*0.35)/3.6 -> 0 | K7: =($R$31*H7*0.35)/3.6 -> 0 | L7: =VLOOKUP(A7,F29:G49,2,FALSE) -> 36 | M7: =L7*J7 -> 0 | N7: =45*($R$31*H7*0.35)/3.6 -> 0 | O7: =SUMPRODUCT(D7:H7, N$31:R$31)*0.35*0.65/3.6 -> 0 | P7: =SUMPRODUCT(D7:H7, N$30:R$30) -> 0 | Q7: =J7*0.8*0.87*30 -> 0 | R7: =IFERROR(M7+N7-O7-P7-Q7,0) -> 0 | S7: =H7*$R$31 -> 0 | T7: =SUMPRODUCT(D7:H7, N$32:R$32)*0.01 -> 0 | U7: =IFERROR(S7/I7,0) -> 0 | V7: =0.1*I7 -> 0 | W7: =SUMPRODUCT($N$31:$Q$31,D7:G7) -> 0 | Y7: =K7-0.1*J7 -> 0
A8: June - Weekday Off-peak | B8: 264 | C8: =B8*1000 -> 264000 | D8: 0 | E8: 0 | F8: 0 | G8: 0 | H8: 0 | I8: =SUMPRODUCT(D8:H8, N$31:R$31) -> 0 | J8: =(SUMPRODUCT(D8:H8, N$31:R$31)*0.35)/3.6 -> 0 | K8: =($R$31*H8*0.35)/3.6 -> 0 | L8: =VLOOKUP(A8,F30:G51,2,FALSE) -> 27 | M8: =L8*J8 -> 0 | N8: =45*($R$31*H8*0.35)/3.6 -> 0 | O8: =SUMPRODUCT(D8:H8, N$31:R$31)*0.35*0.65/3.6 -> 0 | P8: =SUMPRODUCT(D8:H8, N$30:R$30) -> 0 | Q8: =J8*0.8*0.87*30 -> 0 | R8: =IFERROR(M8+N8-O8-P8-Q8,0) -> 0 | S8: =H8*$R$31 -> 0 | T8: =SUMPRODUCT(D8:H8, N$32:R$32)*0.01 -> 0 | U8: =IFERROR(S8/I8,0) -> 0 | V8: =0.1*I8 -> 0 | W8: =SUMPRODUCT($N$31:$Q$31,D8:G8) -> 0 | Y8: =K8-0.1*J8 -> 0
A9: June - Weekend Peak | B9: 96 | C9: =B9*1000 -> 96000 | D9: 0 | E9: 0 | F9: 0 | G9: 0 | H9: 0 | I9: =SUMPRODUCT(D9:H9, N$31:R$31) -> 0 | J9: =(SUMPRODUCT(D9:H9, N$31:R$31)*0.35)/3.6 -> 0 | K9: =($R$31*H9*0.35)/3.6 -> 0 | L9: =VLOOKUP(A9,F31:G52,2,FALSE) -> 33.5 | M9: =L9*J9 -> 0 | N9: =45*($R$31*H9*0.35)/3.6 -> 0 | O9: =SUMPRODUCT(D9:H9, N$31:R$31)*0.35*0.65/3.6 -> 0 | P9: =SUMPRODUCT(D9:H9, N$30:R$30) -> 0 | Q9: =J9*0.8*0.87*30 -> 0 | R9: =IFERROR(M9+N9-O9-P9-Q9,0) -> 0 | S9: =H9*$R$31 -> 0 | T9: =SUMPRODUCT(D9:H9, N$32:R$32)*0.01 -> 0 | U9: =IFERROR(S9/I9,0) -> 0 | V9: =0.1*I9 -> 0 | W9: =SUMPRODUCT($N$31:$Q$31,D9:G9) -> 0 | Y9: =K9-0.1*J9 -> 0
A10: June - Weekend Off-peak | B10: 96 | C10: =B10*1000 -> 96000 | D10: 0 | E10: 0 | F10: 0 | G10: 0 | H10: 0 | I10: =SUMPRODUCT(D10:H10, N$31:R$31) -> 0 | J10: =(SUMPRODUCT(D10:H10, N$31:R$31)*0.35)/3.6 -> 0 | K10: =($R$31*H10*0.35)/3.6 -> 0 | L10: =VLOOKUP(A10,F32:G53,2,FALSE) -> 26.2 | M10: =L10*J10 -> 0 | N10: =45*($R$31*H10*0.35)/3.6 -> 0 | O10: =SUMPRODUCT(D10:H10, N$31:R$31)*0.35*0.65/3.6 -> 0 | P10: =SUMPRODUCT(D10:H10, N$30:R$30) -> 0 | Q10: =J10*0.8*0.87*30 -> 0 | R10: =IFERROR(M10+N10-O10-P10-Q10,0) -> 0 | S10: =H10*$R$31 -> 0 | T10: =SUMPRODUCT(D10:H10, N$32:R$32)*0.01 -> 0 | U10: =IFERROR(S10/I10,0) -> 0 | V10: =0.1*I10 -> 0 | W10: =SUMPRODUCT($N$31:$Q$31,D10:G10) -> 0 | Y10: =K10-0.1*J10 -> 0
A11: July - Weekday Peak | B11: 264 | C11: =B11*1000 -> 264000 | D11: 0 | E11: 0 | F11: 0 | G11: 0 | H11: 0 | I11: =SUMPRODUCT(D11:H11, N$31:R$31) -> 0 | J11: =(SUMPRODUCT(D11:H11, N$31:R$31)*0.35)/3.6 -> 0 | K11: =($R$31*H11*0.35)/3.6 -> 0 | L11: =VLOOKUP(A11,F33:G54,2,FALSE) -> 36.35 | M11: =L11*J11 -> 0 | N11: =45*($R$31*H11*0.35)/3.6 -> 0 | O11: =SUMPRODUCT(D11:H11, N$31:R$31)*0.35*0.65/3.6 -> 0 | P11: =SUMPRODUCT(D11:H11, N$30:R$30) -> 0 | Q11: =J11*0.8*0.87*30 -> 0 | R11: =IFERROR(M11+N11-O11-P11-Q11,0) -> 0 | S11: =H11*$R$31 -> 0 | T11: =SUMPRODUCT(D11:H11, N$32:R$32)*0.01 -> 0 | U11: =IFERROR(S11/I11,0) -> 0 | V11: =0.1*I11 -> 0 | W11: =SUMPRODUCT($N$31:$Q$31,D11:G11) -> 0 | Y11: =K11-0.1*J11 -> 0
A12: July - Weekday Off-peak | B12: 264 | C12: =B12*1000 -> 264000 | D12: 0 | E12: 0 | F12: 0 | G12: 0 | H12: 0 | I12: =SUMPRODUCT(D12:H12, N$31:R$31) -> 0 | J12: =(SUMPRODUCT(D12:H12, N$31:R$31)*0.35)/3.6 -> 0 | K12: =($R$31*H12*0.35)/3.6 -> 0 | L12: =VLOOKUP(A12,F34:G55,2,FALSE) -> 27 | M12: =L12*J12 -> 0 | N12: =45*($R$31*H12*0.35)/3.6 -> 0 | O12: =SUMPRODUCT(D12:H12, N$31:R$31)*0.35*0.65/3.6 -> 0 | P12: =SUMPRODUCT(D12:H12, N$30:R$30) -> 0 | Q12: =J12*0.8*0.87*30 -> 0 | R12: =IFERROR(M12+N12-O12-P12-Q12,0) -> 0 | S12: =H12*$R$31 -> 0 | T12: =SUMPRODUCT(D12:H12, N$32:R$32)*0.01 -> 0 | U12: =IFERROR(S12/I12,0) -> 0 | V12: =0.1*I12 -> 0 | W12: =SUMPRODUCT($N$31:$Q$31,D12:G12) -> 0 | Y12: =K12-0.1*J12 -> 0
A13: July - Weekend Peak | B13: 108 | C13: =B13*1000 -> 108000 | D13: 0 | E13: 0 | F13: 0 | G13: 0 | H13: 0 | I13: =SUMPRODUCT(D13:H13, N$31:R$31) -> 0 | J13: =(SUMPRODUCT(D13:H13, N$31:R$31)*0.35)/3.6 -> 0 | K13: =($R$31*H13*0.35)/3.6 -> 0 | L13: =VLOOKUP(A13,F35:G56,2,FALSE) -> 34.3 | M13: =L13*J13 -> 0 | N13: =45*($R$31*H13*0.35)/3.6 -> 0 | O13: =SUMPRODUCT(D13:H13, N$31:R$31)*0.35*0.65/3.6 -> 0 | P13: =SUMPRODUCT(D13:H13, N$30:R$30) -> 0 | Q13: =J13*0.8*0.87*30 -> 0 | R13: =IFERROR(M13+N13-O13-P13-Q13,0) -> 0 | S13: =H13*$R$31 -> 0 | T13: =SUMPRODUCT(D13:H13, N$32:R$32)*0.01 -> 0 | U13: =IFERROR(S13/I13,0) -> 0 | V13: =0.1*I13 -> 0 | W13: =SUMPRODUCT($N$31:$Q$31,D13:G13) -> 0 | Y13: =K13-0.1*J13 -> 0
A14: July - Weekend Off-peak | B14: 108 | C14: =B14*1000 -> 108000 | D14: 0 | E14: 0 | F14: 0 | G14: 0 | H14: 0 | I14: =SUMPRODUCT(D14:H14, N$31:R$31) -> 0 | J14: =(SUMPRODUCT(D14:H14, N$31:R$31)*0.35)/3.6 -> 0 | K14: =($R$31*H14*0.35)/3.6 -> 0 | L14: =VLOOKUP(A14,F36:G57,2,FALSE) -> 26.3 | M14: =L14*J14 -> 0 | N14: =45*($R$31*H14*0.35)/3.6 -> 0 | O14: =SUMPRODUCT(D14:H14, N$31:R$31)*0.35*0.65/3.6 -> 0 | P14: =SUMPRODUCT(D14:H14, N$30:R$30) -> 0 | Q14: =J14*0.8*0.87*30 -> 0 | R14: =IFERROR(M14+N14-O14-P14-Q14,0) -> 0 | S14: =H14*$R$31 -> 0 | T14: =SUMPRODUCT(D14:H14, N$32:R$32)*0.01 -> 0 | U14: =IFERROR(S14/I14,0) -> 0 | V14: =0.1*I14 -> 0 | W14: =SUMPRODUCT($N$31:$Q$31,D14:G14) -> 0 | Y14: =K14-0.1*J14 -> 0
A15: August - Weekday Peak | B15: 264 | C15: =B15*1000 -> 264000 | D15: 94687.552 | E15: 0 | F15: 0 | G15: 0 | H15: 15085.714 | I15: =SUMPRODUCT(D15:H15, N$31:R$31) -> 2715428.6 | J15: =(SUMPRODUCT(D15:H15, N$31:R$31)*0.35)/3.6 -> 264000 | K15: =($R$31*H15*0.35)/3.6 -> 26400 | L15: =VLOOKUP(A15,F37:G58,2,FALSE) -> 37.65 | M15: =L15*J15 -> 9939600 | N15: =45*($R$31*H15*0.35)/3.6 -> 1188000 | O15: =SUMPRODUCT(D15:H15, N$31:R$31)*0.35*0.65/3.6 -> 171600 | P15: =SUMPRODUCT(D15:H15, N$30:R$30) -> 5142775.4 | Q15: =J15*0.8*0.87*30 -> 5512320 | R15: =IFERROR(M15+N15-O15-P15-Q15,0) -> 300904.65 | S15: =H15*$R$31 -> 271542.86 | T15: =SUMPRODUCT(D15:H15, N$32:R$32)*0.01 -> 1308.1968 | U15: =IFERROR(S15/I15,0) -> 0.1 | V15: =0.1*I15 -> 271542.86 | W15: =SUMPRODUCT($N$31:$Q$31,D15:G15) -> 2443885.7 | Y15: =K15-0.1*J15 -> 0
A16: August - Weekday Off-peak | B16: 264 | C16: =B16*1000 -> 264000 | D16: 0 | E16: 0 | F16: 0 | G16: 0 | H16: 0 | I16: =SUMPRODUCT(D16:H16, N$31:R$31) -> 0 | J16: =(SUMPRODUCT(D16:H16, N$31:R$31)*0.35)/3.6 -> 0 | K16: =($R$31*H16*0.35)/3.6 -> 0 | L16: =VLOOKUP(A16,F38:G59,2,FALSE) -> 28.2 | M16: =L16*J16 -> 0 | N16: =45*($R$31*H16*0.35)/3.6 -> 0 | O16: =SUMPRODUCT(D16:H16, N$31:R$31)*0.35*0.65/3.6 -> 0 | P16: =SUMPRODUCT(D16:H16, N$30:R$30) -> 0 | Q16: =J16*0.8*0.87*30 -> 0 | R16: =IFERROR(M16+N16-O16-P16-Q16,0) -> 0 | S16: =H16*$R$31 -> 0 | T16: =SUMPRODUCT(D16:H16, N$32:R$32)*0.01 -> 0 | U16: =IFERROR(S16/I16,0) -> 0 | V16: =0.1*I16 -> 0 | W16: =SUMPRODUCT($N$31:$Q$31,D16:G16) -> 0 | Y16: =K16-0.1*J16 -> 0
A17: August - Weekend Peak | B17: 108 | C17: =B17*1000 -> 108000 | D17: 0 | E17: 0 | F17: 0 | G17: 0 | H17: 0 | I17: =SUMPRODUCT(D17:H17, N$31:R$31) -> 0 | J17: =(SUMPRODUCT(D17:H17, N$31:R$31)*0.35)/3.6 -> 0 | K17: =($R$31*H17*0.35)/3.6 -> 0 | L17: =VLOOKUP(A17,F39:G60,2,FALSE) -> 35.65 | M17: =L17*J17 -> 0 | N17: =45*($R$31*H17*0.35)/3.6 -> 0 | O17: =SUMPRODUCT(D17:H17, N$31:R$31)*0.35*0.65/3.6 -> 0 | P17: =SUMPRODUCT(D17:H17, N$30:R$30) -> 0 | Q17: =J17*0.8*0.87*30 -> 0 | R17: =IFERROR(M17+N17-O17-P17-Q17,0) -> 0 | S17: =H17*$R$31 -> 0 | T17: =SUMPRODUCT(D17:H17, N$32:R$32)*0.01 -> 0 | U17: =IFERROR(S17/I17,0) -> 0 | V17: =0.1*I17 -> 0 | W17: =SUMPRODUCT($N$31:$Q$31,D17:G17) -> 0 | Y17: =K17-0.1*J17 -> 0
A18: August - Weekend Off-peak | B18: 108 | C18: =B18*1000 -> 108000 | D18: 0 | E18: 0 | F18: 0 | G18: 0 | H18: 0 | I18: =SUMPRODUCT(D18:H18, N$31:R$31) -> 0 | J18: =(SUMPRODUCT(D18:H18, N$31:R$31)*0.35)/3.6 -> 0 | K18: =($R$31*H18*0.35)/3.6 -> 0 | L18: =VLOOKUP(A18,F40:G61,2,FALSE) -> 27.5 | M18: =L18*J18 -> 0 | N18: =45*($R$31*H18*0.35)/3.6 -> 0 | O18: =SUMPRODUCT(D18:H18, N$31:R$31)*0.35*0.65/3.6 -> 0 | P18: =SUMPRODUCT(D18:H18, N$30:R$30) -> 0 | Q18: =J18*0.8*0.87*30 -> 0 | R18: =IFERROR(M18+N18-O18-P18-Q18,0) -> 0 | S18: =H18*$R$31 -> 0 | T18: =SUMPRODUCT(D18:H18, N$32:R$32)*0.01 -> 0 | U18: =IFERROR(S18/I18,0) -> 0 | V18: =0.1*I18 -> 0 | W18: =SUMPRODUCT($N$31:$Q$31,D18:G18) -> 0 | Y18: =K18-0.1*J18 -> 0
A19: September - Weekday Peak | B19: 264 | C19: =B19*1000 -> 264000 | D19: 0 | E19: 0 | F19: 0 | G19: 93278.081 | H19: 15085.714 | I19: =SUMPRODUCT(D19:H19, N$31:R$31) -> 2715428.6 | J19: =(SUMPRODUCT(D19:H19, N$31:R$31)*0.35)/3.6 -> 264000 | K19: =($R$31*H19*0.35)/3.6 -> 26400 | L19: =VLOOKUP(A19,F41:G62,2,FALSE) -> 38.35 | M19: =L19*J19 -> 10124400 | N19: =45*($R$31*H19*0.35)/3.6 -> 1188000 | O19: =SUMPRODUCT(D19:H19, N$31:R$31)*0.35*0.65/3.6 -> 171600 | P19: =SUMPRODUCT(D19:H19, N$30:R$30) -> 5030552.5 | Q19: =J19*0.8*0.87*30 -> 5512320 | R19: =IFERROR(M19+N19-O19-P19-Q19,0) -> 597927.47 | S19: =H19*$R$31 -> 271542.86 | T19: =SUMPRODUCT(D19:H19, N$32:R$32)*0.01 -> 1605.8916 | U19: =IFERROR(S19/I19,0) -> 0.1 | V19: =0.1*I19 -> 271542.86 | W19: =SUMPRODUCT($N$31:$Q$31,D19:G19) -> 2443885.7 | Y19: =K19-0.1*J19 -> 0
... A26: October - Weekend Off-peak | B26: 120 | C26: =B26*1000 -> 120000 | D26: 0 | E26: 0 | F26: 0 | G26: 0 | H26: 0 | I26: =SUMPRODUCT(D26:H26, N$31:R$31) -> 0 | J26: =(SUMPRODUCT(D26:H26, N$31:R$31)*0.35)/3.6 -> 0 | K26: =($R$31*H26*0.35)/3.6 -> 0 | L26: =VLOOKUP(A26,F48:G69,2,FALSE) -> 30.1 | M26: =L26*J26 -> 0 | N26: =45*($R$31*H26*0.35)/3.6 -> 0 | O26: =SUMPRODUCT(D26:H26, N$31:R$31)*0.35*0.65/3.6 -> 0 | P26: =SUMPRODUCT(D26:H26, N$30:R$30) -> 0 | Q26: =J26*0.8*0.87*30 -> 0 | R26: =IFERROR(M26+N26-O26-P26-Q26,0) -> 0 | S26: =H26*$R$31 -> 0 | T26: =SUMPRODUCT(D26:H26, N$32:R$32)*0.01 -> 0 | U26: =IFERROR(S26/I26,0) -> 0 | V26: =0.1*I26 -> 0 | W26: =SUMPRODUCT($N$31:$Q$31,D26:G26) -> 0 | Y26: =K26-0.1*J26 -> 0
A27: Total | C27: =SUM(C7:C26) -> 3672000 | D27: =SUM(D7:D26) -> 94687.552 | E27: =SUM(E7:E26) -> 0 | F27: =SUM(F7:F26) -> 0 | G27: =SUM(G7:G26) -> 224715.38 | H27: =SUM(H7:H26) -> 51428.571 | J27: =SUM(J7:J26) -> 900000 | K27: =SUM(K7:K26) -> 90000 | L27: =SUM(L7:L26) -> 650.15 | M27: =SUM(M7:M26) -> 35720400 | N27: =SUM(N7:N26) -> 4050000 | O27: =SUM(O7:O26) -> 585000 | P27: =SUM(P7:P26) -> 17261834 | Q27: =SUM(Q7:Q26) -> 18792000 | ... T27: =SUM(T7:T26) -> 5176.9355 | V27: =SUM(V7:V26) -> 925714.29 | W27: =SUMPRODUCT($N$31:$Q$31,D27:G27) -> 8331428.6
F29: Period | G29: Electricity_Forward_Price | J29: Scalars | K29: Value | M29: Fuel | N29: Stockpile coal | O29: Colombian coal | P29: Russian coal | Q29: Scottish coal | R29: Wood chips
F30: June - Weekday Peak | G30: 36 | J30: Efficiency | K30: 0.35 | M30: Price_per_t | N30: 42.56 | O30: 43.93 | P30: 43.8 | Q30: 42 | R30: 73.77
F31: June - Weekday Off-peak | G31: 27 | J31: Plant_Capacity_MW | K31: 1000 | M31: CV_GJ_per_t | N31: 25.81 | O31: 25.12 | P31: 24.5 | Q31: 26.2 | R31: 18
F32: June - Weekend Peak | G32: 33.5 | J32: Grid_Charge_per_MWh | K32: 0.65 | M32: SO2_percent | N32: 1.38 | O32: 0.7 | P32: 0.35 | Q32: 1.72 | R32: 0.01
F33: June - Weekend Off-peak | G33: 26.2 | J33: CO2_Intensity_t_per_MWh | K33: 0.8
F34: July - Weekday Peak | G34: 36.35 | J34: CO2_Cost_EUR_per_t | K34: 15
F35: July - Weekday Off-peak | G35: 27 | J35: FX_EUR_per_GBP | K35: 0.87
F36: July - Weekend Peak | G36: 34.3 | J36: ROC_per_MWh | K36: 45
F37: July - Weekend Off-peak | G37: 26.3 | J37: Sulphur_Allowance_t | K37: 9000
F38: August - Weekday Peak | G38: 37.65 | J38: Stockpile_Tonnes | K38: 600000
F39: August - Weekday Off-peak | G39: 28.2 | J39: Biomass_Share_Max | K39: 0.1
F40: August - Weekend Peak | G40: 35.65 | J40: Hours_Peak_per_Day | K40: 12
F41: August - Weekend Off-peak | G41: 27.5 | J41: Hours_Offpeak_per_Day | K41: 12
F42: September - Weekday Peak | G42: 38.35 | J42: P_Colombian_t | K42: 0
F43: September - Weekday Off-peak | G43: 28.5 | J43: P_Russian_t | K43: 0
F44: September - Weekend Peak | G44: 35.8 | J44: P_Scottish_t | K44: 0
F45: September - Weekend Off-peak | G45: 27.65
F46: October - Weekday Peak | G46: 43.7
F47: October - Weekday Off-peak | G47: 31.7
F48: October - Weekend Peak | G48: 38.7
F49: October - Weekend Off-peak | G49: 30.1

Sheet SO2 30£
A6: Month | B6: Hours | C6: Max_Capacity | D6: X_Stockpile_t | E6: X_Colombian_t | F6: X_Russian_t | G6: X_Scottish_t | H6: X_Wood_t | I6: Thermal_Input_GJ | J6: Total_MWh | K6: Wood_Chips_MWh | L6: Price_per MWh | M6: Revenue | N6: ROC_Revenue | O6: Grid_Charge | P6: Fuel_Cost | Q6: CO2_Cost | R6: Profit | S6: Wood_Thermal_GJ | T6: SO2_tonnes | U6: Biomass_share | V6: Thermal_Input_GJ*0.1 | W6: Coal fule | Y6: Wood_Chips_Constraint
A7: June - Weekday Peak | B7: 264 | C7: =B7*1000 -> 264000 | D7: 94687.552 | E7: 0 | F7: 0 | G7: 0 | H7: 15085.714 | I7: =SUMPRODUCT(D7:H7, N$31:R$31) -> 2715428.6 | J7: =(SUMPRODUCT(D7:H7, N$31:R$31)*0.35)/3.6 -> 264000 | K7: =($R$31*H7*0.35)/3.6 -> 26400 | L7: =VLOOKUP(A7,F29:G49,2,FALSE) -> 36 | M7: =L7*J7 -> 9504000 | N7: =45*($R$31*H7*0.35)/3.6 -> 1188000 | O7: =SUMPRODUCT(D7:H7, N$31:R$31)*0.35*0.65/3.6 -> 171600 | P7: =SUMPRODUCT(D7:H7, N$30:R$30) -> 5142775.4 | Q7: =J7*0.8*0.87*15 -> 2756160 | R7: =IFERROR(M7+N7-O7-P7-Q7,0) -> 2621464.6 | S7: =H7*$R$31 -> 271542.86 | T7: =SUMPRODUCT(D7:H7, N$32:R$32)*0.01 -> 1308.1968 | U7: =IFERROR(S7/I7,0) -> 0.1 | V7: =0.1*I7 -> 271542.86 | W7: =SUMPRODUCT($N$31:$Q$31,D7:G7) -> 2443885.7 | Y7: =K7-0.1*J7 -> 0
A8: June - Weekday Off-peak | B8: 264 | C8: =B8*1000 -> 264000 | D8: 0 | E8: 0 | F8: 0 | G8: 0 | H8: 0 | I8: =SUMPRODUCT(D8:H8, N$31:R$31) -> 0 | J8: =(SUMPRODUCT(D8:H8, N$31:R$31)*0.35)/3.6 -> 0 | K8: =($R$31*H8*0.35)/3.6 -> 0 | L8: =VLOOKUP(A8,F30:G51,2,FALSE) -> 27 | M8: =L8*J8 -> 0 | N8: =45*($R$31*H8*0.35)/3.6 -> 0 | O8: =SUMPRODUCT(D8:H8, N$31:R$31)*0.35*0.65/3.6 -> 0 | P8: =SUMPRODUCT(D8:H8, N$30:R$30) -> 0 | Q8: =J8*0.8*0.87*15 -> 0 | R8: =IFERROR(M8+N8-O8-P8-Q8,0) -> 0 | S8: =H8*$R$31 -> 0 | T8: =SUMPRODUCT(D8:H8, N$32:R$32)*0.01 -> 0 | U8: =IFERROR(S8/I8,0) -> 0 | V8: =0.1*I8 -> 0 | W8: =SUMPRODUCT($N$31:$Q$31,D8:G8) -> 0 | Y8: =K8-0.1*J8 -> 0
A9: June - Weekend Peak | B9: 96 | C9: =B9*1000 -> 96000 | D9: 34431.837 | E9: 0 | F9: 0 | G9: 0 | H9: 5485.7143 | I9: =SUMPRODUCT(D9:H9, N$31:R$31) -> 987428.57 | J9: =(SUMPRODUCT(D9:H9, N$31:R$31)*0.35)/3.6 -> 96000 | K9: =($R$31*H9*0.35)/3.6 -> 9600 | L9: =VLOOKUP(A9,F31:G52,2,FALSE) -> 33.5 | M9: =L9*J9 -> 3216000 | N9: =45*($R$31*H9*0.35)/3.6 -> 432000 | O9: =SUMPRODUCT(D9:H9, N$31:R$31)*0.35*0.65/3.6 -> 62400 | P9: =SUMPRODUCT(D9:H9, N$30:R$30) -> 1870100.1 | Q9: =J9*0.8*0.87*15 -> 1002240 | R9: =IFERROR(M9+N9-O9-P9-Q9,0) -> 713259.87 | S9: =H9*$R$31 -> 98742.857 | T9: =SUMPRODUCT(D9:H9, N$32:R$32)*0.01 -> 475.70792 | U9: =IFERROR(S9/I9,0) -> 0.1 | V9: =0.1*I9 -> 98742.857 | W9: =SUMPRODUCT($N$31:$Q$31,D9:G9) -> 888685.71 | Y9: =K9-0.1*J9 -> 0
A10: June - Weekend Off-peak | B10: 96 | C10: =B10*1000 -> 96000 | D10: 0 | E10: 0 | F10: 0 | G10: 0 | H10: 0 | I10: =SUMPRODUCT(D10:H10, N$31:R$31) -> 0 | J10: =(SUMPRODUCT(D10:H10, N$31:R$31)*0.35)/3.6 -> 0 | K10: =($R$31*H10*0.35)/3.6 -> 0 | L10: =VLOOKUP(A10,F32:G53,2,FALSE) -> 26.2 | M10: =L10*J10 -> 0 | N10: =45*($R$31*H10*0.35)/3.6 -> 0 | O10: =SUMPRODUCT(D10:H10, N$31:R$31)*0.35*0.65/3.6 -> 0 | P10: =SUMPRODUCT(D10:H10, N$30:R$30) -> 0 | Q10: =J10*0.8*0.87*15 -> 0 | R10: =IFERROR(M10+N10-O10-P10-Q10,0) -> 0 | S10: =H10*$R$31 -> 0 | T10: =SUMPRODUCT(D10:H10, N$32:R$32)*0.01 -> 0 | U10: =IFERROR(S10/I10,0) -> 0 | V10: =0.1*I10 -> 0 | W10: =SUMPRODUCT($N$31:$Q$31,D10:G10) -> 0 | Y10: =K10-0.1*J10 -> 0
A11: July - Weekday Peak | B11: 264 | C11: =B11*1000 -> 264000 | D11: 94687.552 | E11: 0 | F11: 0 | G11: 0 | H11: 15085.714 | I11: =SUMPRODUCT(D11:H11, N$31:R$31) -> 2715428.6 | J11: =(SUMPRODUCT(D11:H11, N$31:R$31)*0.35)/3.6 -> 264000 | K11: =($R$31*H11*0.35)/3.6 -> 26400 | L11: =VLOOKUP(A11,F33:G54,2,FALSE) -> 36.35 | M11: =L11*J11 -> 9596400 | N11: =45*($R$31*H11*0.35)/3.6 -> 1188000 | O11: =SUMPRODUCT(D11:H11, N$31:R$31)*0.35*0.65/3.6 -> 171600 | P11: =SUMPRODUCT(D11:H11, N$30:R$30) -> 5142775.4 | Q11: =J11*0.8*0.87*15 -> 2756160 | R11: =IFERROR(M11+N11-O11-P11-Q11,0) -> 2713864.6 | S11: =H11*$R$31 -> 271542.86 | T11: =SUMPRODUCT(D11:H11, N$32:R$32)*0.01 -> 1308.1968 | U11: =IFERROR(S11/I11,0) -> 0.1 | V11: =0.1*I11 -> 271542.86 | W11: =SUMPRODUCT($N$31:$Q$31,D11:G11) -> 2443885.7 | Y11: =K11-0.1*J11 -> 0
A12: July - Weekday Off-peak | B12: 264 | C12: =B12*1000 -> 264000 | D12: 70610.505 | E12: 0 | F12: 0 | G12: 0 | H12: 11249.735 | I12: =SUMPRODUCT(D12:H12, N$31:R$31) -> 2024952.4 | J12: =(SUMPRODUCT(D12:H12, N$31:R$31)*0.35)/3.6 -> 196870.37 | K12: =($R$31*H12*0.35)/3.6 -> 19687.037 | L12: =VLOOKUP(A12,F34:G55,2,FALSE) -> 27 | M12: =L12*J12 -> 5315500 | N12: =45*($R$31*H12*0.35)/3.6 -> 885916.67 | O12: =SUMPRODUCT(D12:H12, N$31:R$31)*0.35*0.65/3.6 -> 127965.74 | P12: =SUMPRODUCT(D12:H12, N$30:R$30) -> 3835076.1 | Q12: =J12*0.8*0.87*15 -> 2055326.7 | R12: =IFERROR(M12+N12-O12-P12-Q12,0) -> 183048.17 | S12: =H12*$R$31 -> 202495.24 | T12: =SUMPRODUCT(D12:H12, N$32:R$32)*0.01 -> 975.54995 | U12: =IFERROR(S12/I12,0) -> 0.1 | V12: =0.1*I12 -> 202495.24 | W12: =SUMPRODUCT($N$31:$Q$31,D12:G12) -> 1822457.1 | Y12: =K12-0.1*J12 -> 0
A13: July - Weekend Peak | B13: 108 | C13: =B13*1000 -> 108000 | D13: 38735.817 | E13: 0 | F13: 0 | G13: 0 | H13: 6171.4286 | I13: =SUMPRODUCT(D13:H13, N$31:R$31) -> 1110857.1 | J13: =(SUMPRODUCT(D13:H13, N$31:R$31)*0.35)/3.6 -> 108000 | K13: =($R$31*H13*0.35)/3.6 -> 10800 | L13: =VLOOKUP(A13,F35:G56,2,FALSE) -> 34.3 | M13: =L13*J13 -> 3704400 | N13: =45*($R$31*H13*0.35)/3.6 -> 486000 | O13: =SUMPRODUCT(D13:H13, N$31:R$31)*0.35*0.65/3.6 -> 70200 | P13: =SUMPRODUCT(D13:H13, N$30:R$30) -> 2103862.6 | Q13: =J13*0.8*0.87*15 -> 1127520 | R13: =IFERROR(M13+N13-O13-P13-Q13,0) -> 888817.36 | S13: =H13*$R$31 -> 111085.71 | T13: =SUMPRODUCT(D13:H13, N$32:R$32)*0.01 -> 535.17141 | U13: =IFERROR(S13/I13,0) -> 0.1 | V13: =0.1*I13 -> 111085.71 | W13: =SUMPRODUCT($N$31:$Q$31,D13:G13) -> 999771.43 | Y13: =K13-0.1*J13 -> 0
A14: July - Weekend Off-peak | B14: 108 | C14: =B14*1000 -> 108000 | D14: 0 | E14: 0 | F14: 0 | G14: 0 | H14: 0 | I14: =SUMPRODUCT(D14:H14, N$31:R$31) -> 0 | J14: =(SUMPRODUCT(D14:H14, N$31:R$31)*0.35)/3.6 -> 0 | K14: =($R$31*H14*0.35)/3.6 -> 0 | L14: =VLOOKUP(A14,F36:G57,2,FALSE) -> 26.3 | M14: =L14*J14 -> 0 | N14: =45*($R$31*H14*0.35)/3.6 -> 0 | O14: =SUMPRODUCT(D14:H14, N$31:R$31)*0.35*0.65/3.6 -> 0 | P14: =SUMPRODUCT(D14:H14, N$30:R$30) -> 0 | Q14: =J14*0.8*0.87*15 -> 0 | R14: =IFERROR(M14+N14-O14-P14-Q14,0) -> 0 | S14: =H14*$R$31 -> 0 | T14: =SUMPRODUCT(D14:H14, N$32:R$32)*0.01 -> 0 | U14: =IFERROR(S14/I14,0) -> 0 | V14: =0.1*I14 -> 0 | W14: =SUMPRODUCT($N$31:$Q$31,D14:G14) -> 0 | Y14: =K14-0.1*J14 -> 0
A15: August - Weekday Peak | B15: 264 | C15: =B15*1000 -> 264000 | D15: 94687.552 | E15: 0 | F15: 0 | G15: 0 | H15: 15085.714 | I15: =SUMPRODUCT(D15:H15, N$31:R$31) -> 2715428.6 | J15: =(SUMPRODUCT(D15:H15, N$31:R$31)*0.35)/3.6 -> 264000 | K15: =($R$31*H15*0.35)/3.6 -> 26400 | L15: =VLOOKUP(A15,F37:G58,2,FALSE) -> 37.65 | M15: =L15*J15 -> 9939600 | N15: =45*($R$31*H15*0.35)/3.6 -> 1188000 | O15: =SUMPRODUCT(D15:H15, N$31:R$31)*0.35*0.65/3.6 -> 171600 | P15: =SUMPRODUCT(D15:H15, N$30:R$30) -> 5142775.4 | Q15: =J15*0.8*0.87*15 -> 2756160 | R15: =IFERROR(M15+N15-O15-P15-Q15,0) -> 3057064.6 | S15: =H15*$R$31 -> 271542.86 | T15: =SUMPRODUCT(D15:H15, N$32:R$32)*0.01 -> 1308.1968 | U15: =IFERROR(S15/I15,0) -> 0.1 | V15: =0.1*I15 -> 271542.86 | W15: =SUMPRODUCT($N$31:$Q$31,D15:G15) -> 2443885.7 | Y15: =K15-0.1*J15 -> 0
A16: August - Weekday Off-peak | B16: 264 | C16: =B16*1000 -> 264000 | D16: 94687.552 | E16: 0 | F16: 0 | G16: 0 | H16: 15085.714 | I16: =SUMPRODUCT(D16:H16, N$31:R$31) -> 2715428.6 | J16: =(SUMPRODUCT(D16:H16, N$31:R$31)*0.35)/3.6 -> 264000 | K16: =($R$31*H16*0.35)/3.6 -> 26400 | L16: =VLOOKUP(A16,F38:G59,2,FALSE) -> 28.2 | M16: =L16*J16 -> 7444800 | N16: =45*($R$31*H16*0.35)/3.6 -> 1188000 | O16: =SUMPRODUCT(D16:H16, N$31:R$31)*0.35*0.65/3.6 -> 171600 | P16: =SUMPRODUCT(D16:H16, N$30:R$30) -> 5142775.4 | Q16: =J16*0.8*0.87*15 -> 2756160 | R16: =IFERROR(M16+N16-O16-P16-Q16,0) -> 562264.65 | S16: =H16*$R$31 -> 271542.86 | T16: =SUMPRODUCT(D16:H16, N$32:R$32)*0.01 -> 1308.1968 | U16: =IFERROR(S16/I16,0) -> 0.1 | V16: =0.1*I16 -> 271542.86 | W16: =SUMPRODUCT($N$31:$Q$31,D16:G16) -> 2443885.7 | Y16: =K16-0.1*J16 -> 0
A17: August - Weekend Peak | B17: 108 | C17: =B17*1000 -> 108000 | D17: 38735.817 | E17: 0 | F17: 0 | G17: 0 | H17: 6171.4286 | I17: =SUMPRODUCT(D17:H17, N$31:R$31) -> 1110857.1 | J17: =(SUMPRODUCT(D17:H17, N$31:R$31)*0.35)/3.6 -> 108000 | K17: =($R$31*H17*0.35)/3.6 -> 10800 | L17: =VLOOKUP(A17,F39:G60,2,FALSE) -> 35.65 | M17: =L17*J17 -> 3850200 | N17: =45*($R$31*H17*0.35)/3.6 -> 486000 | O17: =SUMPRODUCT(D17:H17, N$31:R$31)*0.35*0.65/3.6 -> 70200 | P17: =SUMPRODUCT(D17:H17, N$30:R$30) -> 2103862.6 | Q17: =J17*0.8*0.87*15 -> 1127520 | R17: =IFERROR(M17+N17-O17-P17-Q17,0) -> 1034617.4 | S17: =H17*$R$31 -> 111085.71 | T17: =SUMPRODUCT(D17:H17, N$32:R$32)*0.01 -> 535.17141 | U17: =IFERROR(S17/I17,0) -> 0.1 | V17: =0.1*I17 -> 111085.71 | W17: =SUMPRODUCT($N$31:$Q$31,D17:G17) -> 999771.43 | Y17: =K17-0.1*J17 -> 0
A18: August - Weekend Off-peak | B18: 108 | C18: =B18*1000 -> 108000 | D18: 38735.817 | E18: 0 | F18: 0 | G18: 0 | H18: 6171.4286 | I18: =SUMPRODUCT(D18:H18, N$31:R$31) -> 1110857.1 | J18: =(SUMPRODUCT(D18:H18, N$31:R$31)*0.35)/3.6 -> 108000 | K18: =($R$31*H18*0.35)/3.6 -> 10800 | L18: =VLOOKUP(A18,F40:G61,2,FALSE) -> 27.5 | M18: =L18*J18 -> 2970000 | N18: =45*($R$31*H18*0.35)/3.6 -> 486000 | O18: =SUMPRODUCT(D18:H18, N$31:R$31)*0.35*0.65/3.6 -> 70200 | P18: =SUMPRODUCT(D18:H18, N$30:R$30) -> 2103862.6 | Q18: =J18*0.8*0.87*15 -> 1127520 | R18: =IFERROR(M18+N18-O18-P18-Q18,0) -> 154417.36 | S18: =H18*$R$31 -> 111085.71 | T18: =SUMPRODUCT(D18:H18, N$32:R$32)*0.01 -> 535.17141 | U18: =IFERROR(S18/I18,0) -> 0.1 | V18: =0.1*I18 -> 111085.71 | W18: =SUMPRODUCT($N$31:$Q$31,D18:G18) -> 999771.43 | Y18: =K18-0.1*J18 -> 0
A19: September - Weekday Peak | B19: 264 | C19: =B19*1000 -> 264000 | D19: 0 | E19: 0 | F19: 0 | G19: 93278.081 | H19: 15085.714 | I19: =SUMPRODUCT(D19:H19, N$31:R$31) -> 2715428.6 | J19: =(SUMPRODUCT(D19:H19, N$31:R$31)*0.35)/3.6 -> 264000 | K19: =($R$31*H19*0.35)/3.6 -> 26400 | L19: =VLOOKUP(A19,F41:G62,2,FALSE) -> 38.35 | M19: =L19*J19 -> 10124400 | N19: =45*($R$31*H19*0.35)/3.6 -> 1188000 | O19: =SUMPRODUCT(D19:H19, N$31:R$31)*0.35*0.65/3.6 -> 171600 | P19: =SUMPRODUCT(D19:H19, N$30:R$30) -> 5030552.5 | Q19: =J19*0.8*0.87*15 -> 2756160 | R19: =IFERROR(M19+N19-O19-P19-Q19,0) -> 3354087.5 | S19: =H19*$R$31 -> 271542.86 | T19: =SUMPRODUCT(D19:H19, N$32:R$32)*0.01 -> 1605.8916 | U19: =IFERROR(S19/I19,0) -> 0.1 | V19: =0.1*I19 -> 271542.86 | W19: =SUMPRODUCT($N$31:$Q$31,D19:G19) -> 2443885.7 | Y19: =K19-0.1*J19 -> 0
... A26: October - Weekend Off-peak | B26: 120 | C26: =B26*1000 -> 120000 | D26: 0 | E26: 0 | F26: 0 | G26: 42399.128 | H26: 6857.1429 | I26: =SUMPRODUCT(D26:H26, N$31:R$31) -> 1234285.7 | J26: =(SUMPRODUCT(D26:H26, N$31:R$31)*0.35)/3.6 -> 120000 | K26: =($R$31*H26*0.35)/3.6 -> 12000 | L26: =VLOOKUP(A26,F48:G69,2,FALSE) -> 30.1 | M26: =L26*J26 -> 3612000 | N26: =45*($R$31*H26*0.35)/3.6 -> 540000 | O26: =SUMPRODUCT(D26:H26, N$31:R$31)*0.35*0.65/3.6 -> 78000 | P26: =SUMPRODUCT(D26:H26, N$30:R$30) -> 2286614.8 | Q26: =J26*0.8*0.87*15 -> 1252800 | R26: =IFERROR(M26+N26-O26-P26-Q26,0) -> 534585.21 | S26: =H26*$R$31 -> 123428.57 | T26: =SUMPRODUCT(D26:H26, N$32:R$32)*0.01 -> 729.95071 | U26: =IFERROR(S26/I26,0) -> 0.1 | V26: =0.1*I26 -> 123428.57 | W26: =SUMPRODUCT($N$31:$Q$31,D26:G26) -> 1110857.1 | Y26: =K26-0.1*J26 -> 0
A27: Total | C27: =SUM(C7:C26) -> 3672000 | D27: =SUM(D7:D26) -> 600000 | E27: =SUM(E7:E26) -> 0 | F27: =SUM(F7:F26) -> 0 | G27: =SUM(G7:G26) -> 517269.36 | H27: =SUM(H7:H26) -> 179249.74 | J27: =SUM(J7:J26) -> 3136870.4 | K27: =SUM(K7:K26) -> 313687.04 | L27: =SUM(L7:L26) -> 650.15 | M27: =SUM(M7:M26) -> 1.065373e+08 | N27: =SUM(N7:N26) -> 14115917 | O27: =SUM(O7:O26) -> 2038965.7 | P27: =SUM(P7:P26) -> 60484566 | Q27: =SUM(Q7:Q26) -> 32748927 | R27: =SUM(R7:R26)-T27*30 -> 24864910 | S27: =SUM(S7:S26) -> 3226495.2 | T27: =SUM(T7:T26) -> 17194.958 | V27: =SUM(V7:V26) -> 3226495.2 | W27: =SUMPRODUCT($N$31:$Q$31,D27:G27) -> 29038457
F29: Period | G29: Electricity_Forward_Price | J29: Scalars | K29: Value | M29: Fuel | N29: Stockpile coal | O29: Colombian coal | P29: Russian coal | Q29: Scottish coal | R29: Wood chips
F30: June - Weekday Peak | G30: 36 | J30: Efficiency | K30: 0.35 | M30: Price_per_t | N30: 42.56 | O30: 43.93 | P30: 43.8 | Q30: 42 | R30: 73.77
F31: June - Weekday Off-peak | G31: 27 | J31: Plant_Capacity_MW | K31: 1000 | M31: CV_GJ_per_t | N31: 25.81 | O31: 25.12 | P31: 24.5 | Q31: 26.2 | R31: 18
F32: June - Weekend Peak | G32: 33.5 | J32: Grid_Charge_per_MWh | K32: 0.65 | M32: SO2_percent | N32: 1.38 | O32: 0.7 | P32: 0.35 | Q32: 1.72 | R32: 0.01
F33: June - Weekend Off-peak | G33: 26.2 | J33: CO2_Intensity_t_per_MWh | K33: 0.8
F34: July - Weekday Peak | G34: 36.35 | J34: CO2_Cost_EUR_per_t | K34: 15
F35: July - Weekday Off-peak | G35: 27 | J35: FX_EUR_per_GBP | K35: 0.87
F36: July - Weekend Peak | G36: 34.3 | J36: ROC_per_MWh | K36: 45
